<?xml version="1.0" ?>
<!-- =================================================================================== -->
<!-- |    This document was autogenerated by xacro from urdf/robot.xacro               | -->
<!-- |    EDITING THIS FILE BY HAND IS NOT RECOMMENDED                                 | -->
<!-- =================================================================================== -->
<robot name="robot">
  <material name="black">
    <color rgba="0.0 0.0 0.0 1.0"/>
  </material>
  <material name="blue">
    <color rgba="0.0 0.0 0.8 1.0"/>
  </material>
  <material name="green">
    <color rgba="0.0 0.8 0.0 1.0"/>
  </material>
  <material name="grey">
    <color rgba="0.2 0.2 0.2 1.0"/>
  </material>
  <material name="silver">
    <color rgba="0.9137254901960784 0.9137254901960784 0.8470588235294118 1.0"/>
  </material>
  <material name="orange">
    <color rgba="1.0 0.4235294117647059 0.0392156862745098 1.0"/>
  </material>
  <material name="brown">
    <color rgba="0.8705882352941177 0.8117647058823529 0.7647058823529411 1.0"/>
  </material>
  <material name="red">
    <color rgba="0.8 0.0 0.0 1.0"/>
  </material>
  <material name="white">
    <color rgba="1.0 1.0 1.0 1.0"/>
  </material>
  <!-- ros_control plugin -->
  <gazebo>
    <plugin filename="liblegged_hw_sim.so" name="gazebo_ros_control">
      <robotNamespace>/</robotNamespace>
      <robotParam>legged_robot_description</robotParam>
      <robotSimType>legged_gazebo/LeggedHWSim</robotSimType>
    </plugin>
  </gazebo>
  <gazebo>
    <plugin filename="libgazebo_ros_p3d.so" name="p3d_base_controller">
      <alwaysOn>true</alwaysOn>
      <updateRate>1000.0</updateRate>
      <bodyName>base</bodyName>
      <topicName>ground_truth/state</topicName>
      <gaussianNoise>0</gaussianNoise>
      <frameName>world</frameName>
      <xyzOffsets>0 0 0</xyzOffsets>
      <rpyOffsets>0 0 0</rpyOffsets>
    </plugin>
  </gazebo>
  <link name="base">
    <visual>
      <origin rpy="0 0 0" xyz="0 0 0"/>
      <geometry>
        <mesh filename="package://biqu_go1_description/go1_meshes/trunk.dae" scale="1 1 1"/>
      </geometry>
    </visual>
    <collision>
      <origin rpy="0 0 0" xyz="0 0 0"/>
      <geometry>
        <box size="0.3762 0.0935 0.114"/>
      </geometry>
    </collision>
    <inertial>
      <origin rpy="0 0 0" xyz="0.0223 0.002 -0.0005"/>
      <mass value="5.204"/>
      <inertia ixx="0.0168128557" ixy="-0.0002296769" ixz="-0.0002945293" iyy="0.063009565" iyz="-4.18731e-05" izz="0.0716547275"/>
    </inertial>
  </link>
  <!-- Imu is fixed to the base link -->
  <joint name="unitree_imu_joint" type="fixed">
    <origin rpy="0. 0. 0." xyz="0. 0. 0."/>
    <parent link="base"/>
    <child link="unitree_imu"/>
  </joint>
  <!-- Imu link -->
  <link name="unitree_imu">
    <inertial>
      <mass value="0.01"/>
      <origin rpy="0 0 0" xyz="0 0 0"/>
      <inertia ixx="0.000001" ixy="0" ixz="0" iyy="0.000001" iyz="0" izz="0.000001"/>
    </inertial>
    <visual>
      <origin rpy="0 0 0" xyz="0 0 0"/>
      <geometry>
        <box size="0.015 0.015 0.004"/>
      </geometry>
    </visual>
    <material name="orange">
      <color rgba="255 108 10 255"/>
    </material>
  </link>
  <gazebo reference="unitree_imu">
    <material>Gazebo/Orange</material>
  </gazebo>
  <gazebo reference="unitree_imu_joint">
    <disableFixedJointLumping>true</disableFixedJointLumping>
  </gazebo>
  <joint name="RF_HAA" type="revolute">
    <origin rpy="0 0 0" xyz="0.1881 -0.04675 0"/>
    <parent link="base"/>
    <child link="RF_hip"/>
    <axis xyz="1 0 0"/>
    <dynamics damping="0.01" friction="0.2"/>
    <limit effort="23.7" lower="-0.863" upper="0.863" velocity="30.1"/>
  </joint>
  <link name="RF_hip">
    <visual>
      <origin rpy="3.141592653589793 0 0" xyz="0 0 0"/>
      <geometry>
        <mesh filename="package://biqu_go1_description/go1_meshes/hip.dae" scale="1 1 1"/>
      </geometry>
      <material name="orange"/>
    </visual>
    <collision>
      <origin rpy="1.5707963267948966 0 0" xyz="0 0 0"/>
      <geometry>
        <cylinder length="0.04" radius="0.046"/>
      </geometry>
    </collision>
    <inertial>
      <origin rpy="0 0 0" xyz="-0.005657 0.008752 -0.000102"/>
      <mass value="0.591"/>
      <inertia ixx="0.000334008405" ixy="1.0826066e-05" ixz="1.290732e-06" iyy="0.000619101213" iyz="-1.643194e-06" izz="0.00040057614"/>
    </inertial>
  </link>
  <joint name="RF_HFE" type="revolute">
    <origin rpy="0 0 0" xyz="0 -0.08 0"/>
    <parent link="RF_hip"/>
    <child link="RF_thigh"/>
    <axis xyz="0 1 0"/>
    <dynamics damping="0.01" friction="0.2"/>
    <limit effort="23.7" lower="-0.686" upper="4.501" velocity="30.1"/>
  </joint>
  <link name="RF_thigh">
    <visual>
      <origin rpy="0 0 0" xyz="0 0 0"/>
      <geometry>
        <mesh filename="package://biqu_go1_description/go1_meshes/thigh_mirror.dae" scale="1 1 1"/>
      </geometry>
      <material name="orange"/>
    </visual>
    <collision>
      <origin rpy="0 1.6707963267948966 0" xyz="-0.015 0 -0.1065"/>
      <geometry>
        <box size="0.213 0.0245 0.034"/>
      </geometry>
    </collision>
    <collision>
      <origin rpy="1.5707963267948966 0 0" xyz="0 0.008 0"/>
      <geometry>
        <cylinder length="0.032" radius="0.041"/>
      </geometry>
    </collision>
    <inertial>
      <origin rpy="0 0 0" xyz="-0.003342 0.018054 -0.033451"/>
      <mass value="0.92"/>
      <inertia ixx="0.004431760472" ixy="-5.7496807e-05" ixz="-0.000218457134" iyy="0.004485671726" iyz="-0.000572001265" izz="0.000740309489"/>
    </inertial>
  </link>
  <joint name="RF_KFE" type="revolute">
    <origin rpy="0 0 0" xyz="0 0 -0.213"/>
    <parent link="RF_thigh"/>
    <child link="RF_calf"/>
    <axis xyz="0 1 0"/>
    <dynamics damping="0.01" friction="0.2"/>
    <limit effort="35.55" lower="-2.818" upper="-0.888" velocity="20.06"/>
  </joint>
  <link name="RF_calf">
    <visual>
      <origin rpy="0 0 0" xyz="0 0 0"/>
      <geometry>
        <mesh filename="package://biqu_go1_description/go1_meshes/calf.dae" scale="1 1 1"/>
      </geometry>
      <material name="orange"/>
    </visual>
    <collision>
      <origin rpy="0 1.5707963267948966 0" xyz="0.0 0 -0.1065"/>
      <geometry>
        <box size="0.213 0.016 0.016"/>
      </geometry>
    </collision>
    <inertial>
      <origin rpy="0 0 0" xyz="0.006197 0.001408 -0.116695"/>
      <mass value="0.135862"/>
      <inertia ixx="0.001088793059" ixy="-2.55679e-07" ixz="7.117814e-06" iyy="0.001100428748" iyz="2.077264e-06" izz="2.4787446e-05"/>
    </inertial>
  </link>
  <joint name="RF_foot_fixed" type="fixed">
    <origin rpy="0 0 0" xyz="0 0 -0.213"/>
    <parent link="RF_calf"/>
    <child link="RF_FOOT"/>
  </joint>
  <link name="RF_FOOT">
    <visual>
      <origin rpy="0 0 0" xyz="0 0 0"/>
      <geometry>
        <sphere radius="0.01"/>
      </geometry>
      <material name="orange"/>
    </visual>
    <collision>
      <origin rpy="0 0 0" xyz="0 0 0"/>
      <geometry>
        <sphere radius="0.02"/>
      </geometry>
    </collision>
    <inertial>
      <mass value="0.06"/>
      <inertia ixx="9.600000000000001e-06" ixy="0.0" ixz="0.0" iyy="9.600000000000001e-06" iyz="0.0" izz="9.600000000000001e-06"/>
    </inertial>
  </link>
  <gazebo reference="RF_foot_fixed">
    <disableFixedJointLumping>true</disableFixedJointLumping>
  </gazebo>
  <gazebo reference="RF_hip">
    <mu1>0.2</mu1>
    <mu2>0.2</mu2>
    <material>Gazebo/DarkGrey</material>
  </gazebo>
  <gazebo reference="RF_thigh">
    <mu1>0.2</mu1>
    <mu2>0.2</mu2>
    <self_collide>0</self_collide>
    <material>Gazebo/DarkGrey</material>
    <kp value="1000000.0"/>
    <kd value="100.0"/>
  </gazebo>
  <gazebo reference="RF_calf">
    <mu1>0.6</mu1>
    <mu2>0.6</mu2>
    <self_collide>1</self_collide>
  </gazebo>
  <gazebo reference="RF_FOOT">
    <mu1>0.6</mu1>
    <mu2>0.6</mu2>
    <self_collide>1</self_collide>
    <material>Gazebo/DarkGrey</material>
    <kp value="1000000.0"/>
    <kd value="100.0"/>
  </gazebo>
  <transmission name="RF_HAA_tran">
    <type>transmission_interface/SimpleTransmission</type>
    <joint name="RF_HAA">
      <hardwareInterface>hardware_interface/EffortJointInterface</hardwareInterface>
    </joint>
    <actuator name="RF_HAA_motor">
      <hardwareInterface>hardware_interface/EffortJointInterface</hardwareInterface>
      <mechanicalReduction>1</mechanicalReduction>
    </actuator>
  </transmission>
  <transmission name="RF_HFE_tran">
    <type>transmission_interface/SimpleTransmission</type>
    <joint name="RF_HFE">
      <hardwareInterface>hardware_interface/EffortJointInterface</hardwareInterface>
    </joint>
    <actuator name="RF_HFE_motor">
      <hardwareInterface>hardware_interface/EffortJointInterface</hardwareInterface>
      <mechanicalReduction>1</mechanicalReduction>
    </actuator>
  </transmission>
  <transmission name="RF_KFE_tran">
    <type>transmission_interface/SimpleTransmission</type>
    <joint name="RF_KFE">
      <hardwareInterface>hardware_interface/EffortJointInterface</hardwareInterface>
    </joint>
    <actuator name="RF_KFE_motor">
      <hardwareInterface>hardware_interface/EffortJointInterface</hardwareInterface>
      <mechanicalReduction>1</mechanicalReduction>
    </actuator>
  </transmission>
  <joint name="LF_HAA" type="revolute">
    <origin rpy="0 0 0" xyz="0.1881 0.04675 0"/>
    <parent link="base"/>
    <child link="LF_hip"/>
    <axis xyz="1 0 0"/>
    <dynamics damping="0.01" friction="0.2"/>
    <limit effort="23.7" lower="-0.863" upper="0.863" velocity="30.1"/>
  </joint>
  <link name="LF_hip">
    <visual>
      <origin rpy="0 0 0" xyz="0 0 0"/>
      <geometry>
        <mesh filename="package://biqu_go1_description/go1_meshes/hip.dae" scale="1 1 1"/>
      </geometry>
      <material name="orange"/>
    </visual>
    <collision>
      <origin rpy="1.5707963267948966 0 0" xyz="0 0 0"/>
      <geometry>
        <cylinder length="0.04" radius="0.046"/>
      </geometry>
    </collision>
    <inertial>
      <origin rpy="0 0 0" xyz="-0.005657 -0.008752 -0.000102"/>
      <mass value="0.591"/>
      <inertia ixx="0.000334008405" ixy="-1.0826066e-05" ixz="1.290732e-06" iyy="0.000619101213" iyz="1.643194e-06" izz="0.00040057614"/>
    </inertial>
  </link>
  <joint name="LF_HFE" type="revolute">
    <origin rpy="0 0 0" xyz="0 0.08 0"/>
    <parent link="LF_hip"/>
    <child link="LF_thigh"/>
    <axis xyz="0 1 0"/>
    <dynamics damping="0.01" friction="0.2"/>
    <limit effort="23.7" lower="-0.686" upper="4.501" velocity="30.1"/>
  </joint>
  <link name="LF_thigh">
    <visual>
      <origin rpy="0 0 0" xyz="0 0 0"/>
      <geometry>
        <mesh filename="package://biqu_go1_description/go1_meshes/thigh.dae" scale="1 1 1"/>
      </geometry>
      <material name="orange"/>
    </visual>
    <collision>
      <origin rpy="0 1.6707963267948966 0" xyz="-0.015 0 -0.1065"/>
      <geometry>
        <box size="0.213 0.0245 0.034"/>
      </geometry>
    </collision>
    <collision>
      <origin rpy="1.5707963267948966 0 0" xyz="0 -0.008 0"/>
      <geometry>
        <cylinder length="0.032" radius="0.041"/>
      </geometry>
    </collision>
    <inertial>
      <origin rpy="0 0 0" xyz="-0.003342 -0.018054 -0.033451"/>
      <mass value="0.92"/>
      <inertia ixx="0.004431760472" ixy="5.7496807e-05" ixz="-0.000218457134" iyy="0.004485671726" iyz="0.000572001265" izz="0.000740309489"/>
    </inertial>
  </link>
  <joint name="LF_KFE" type="revolute">
    <origin rpy="0 0 0" xyz="0 0 -0.213"/>
    <parent link="LF_thigh"/>
    <child link="LF_calf"/>
    <axis xyz="0 1 0"/>
    <dynamics damping="0.01" friction="0.2"/>
    <limit effort="35.55" lower="-2.818" upper="-0.888" velocity="20.06"/>
  </joint>
  <link name="LF_calf">
    <visual>
      <origin rpy="0 0 0" xyz="0 0 0"/>
      <geometry>
        <mesh filename="package://biqu_go1_description/go1_meshes/calf.dae" scale="1 1 1"/>
      </geometry>
      <material name="orange"/>
    </visual>
    <collision>
      <origin rpy="0 1.5707963267948966 0" xyz="0.0 0 -0.1065"/>
      <geometry>
        <box size="0.213 0.016 0.016"/>
      </geometry>
    </collision>
    <inertial>
      <origin rpy="0 0 0" xyz="0.006197 0.001408 -0.116695"/>
      <mass value="0.135862"/>
      <inertia ixx="0.001088793059" ixy="-2.55679e-07" ixz="7.117814e-06" iyy="0.001100428748" iyz="2.077264e-06" izz="2.4787446e-05"/>
    </inertial>
  </link>
  <joint name="LF_foot_fixed" type="fixed">
    <origin rpy="0 0 0" xyz="0 0 -0.213"/>
    <parent link="LF_calf"/>
    <child link="LF_FOOT"/>
  </joint>
  <link name="LF_FOOT">
    <visual>
      <origin rpy="0 0 0" xyz="0 0 0"/>
      <geometry>
        <sphere radius="0.01"/>
      </geometry>
      <material name="orange"/>
    </visual>
    <collision>
      <origin rpy="0 0 0" xyz="0 0 0"/>
      <geometry>
        <sphere radius="0.02"/>
      </geometry>
    </collision>
    <inertial>
      <mass value="0.06"/>
      <inertia ixx="9.600000000000001e-06" ixy="0.0" ixz="0.0" iyy="9.600000000000001e-06" iyz="0.0" izz="9.600000000000001e-06"/>
    </inertial>
  </link>
  <gazebo reference="LF_foot_fixed">
    <disableFixedJointLumping>true</disableFixedJointLumping>
  </gazebo>
  <gazebo reference="LF_hip">
    <mu1>0.2</mu1>
    <mu2>0.2</mu2>
    <material>Gazebo/DarkGrey</material>
  </gazebo>
  <gazebo reference="LF_thigh">
    <mu1>0.2</mu1>
    <mu2>0.2</mu2>
    <self_collide>0</self_collide>
    <material>Gazebo/DarkGrey</material>
    <kp value="1000000.0"/>
    <kd value="100.0"/>
  </gazebo>
  <gazebo reference="LF_calf">
    <mu1>0.6</mu1>
    <mu2>0.6</mu2>
    <self_collide>1</self_collide>
  </gazebo>
  <gazebo reference="LF_FOOT">
    <mu1>0.6</mu1>
    <mu2>0.6</mu2>
    <self_collide>1</self_collide>
    <material>Gazebo/DarkGrey</material>
    <kp value="1000000.0"/>
    <kd value="100.0"/>
  </gazebo>
  <transmission name="LF_HAA_tran">
    <type>transmission_interface/SimpleTransmission</type>
    <joint name="LF_HAA">
      <hardwareInterface>hardware_interface/EffortJointInterface</hardwareInterface>
    </joint>
    <actuator name="LF_HAA_motor">
      <hardwareInterface>hardware_interface/EffortJointInterface</hardwareInterface>
      <mechanicalReduction>1</mechanicalReduction>
    </actuator>
  </transmission>
  <transmission name="LF_HFE_tran">
    <type>transmission_interface/SimpleTransmission</type>
    <joint name="LF_HFE">
      <hardwareInterface>hardware_interface/EffortJointInterface</hardwareInterface>
    </joint>
    <actuator name="LF_HFE_motor">
      <hardwareInterface>hardware_interface/EffortJointInterface</hardwareInterface>
      <mechanicalReduction>1</mechanicalReduction>
    </actuator>
  </transmission>
  <transmission name="LF_KFE_tran">
    <type>transmission_interface/SimpleTransmission</type>
    <joint name="LF_KFE">
      <hardwareInterface>hardware_interface/EffortJointInterface</hardwareInterface>
    </joint>
    <actuator name="LF_KFE_motor">
      <hardwareInterface>hardware_interface/EffortJointInterface</hardwareInterface>
      <mechanicalReduction>1</mechanicalReduction>
    </actuator>
  </transmission>
  <joint name="RH_HAA" type="revolute">
    <origin rpy="0 0 0" xyz="-0.1881 -0.04675 0"/>
    <parent link="base"/>
    <child link="RH_hip"/>
    <axis xyz="1 0 0"/>
    <dynamics damping="0.01" friction="0.2"/>
    <limit effort="23.7" lower="-0.863" upper="0.863" velocity="30.1"/>
  </joint>
  <link name="RH_hip">
    <visual>
      <origin rpy="3.141592653589793 3.141592653589793 0" xyz="0 0 0"/>
      <geometry>
        <mesh filename="package://biqu_go1_description/go1_meshes/hip.dae" scale="1 1 1"/>
      </geometry>
      <material name="orange"/>
    </visual>
    <collision>
      <origin rpy="1.5707963267948966 0 0" xyz="0 0 0"/>
      <geometry>
        <cylinder length="0.04" radius="0.046"/>
      </geometry>
    </collision>
    <inertial>
      <origin rpy="0 0 0" xyz="0.005657 0.008752 -0.000102"/>
      <mass value="0.591"/>
      <inertia ixx="0.000334008405" ixy="-1.0826066e-05" ixz="-1.290732e-06" iyy="0.000619101213" iyz="-1.643194e-06" izz="0.00040057614"/>
    </inertial>
  </link>
  <joint name="RH_HFE" type="revolute">
    <origin rpy="0 0 0" xyz="0 -0.08 0"/>
    <parent link="RH_hip"/>
    <child link="RH_thigh"/>
    <axis xyz="0 1 0"/>
    <dynamics damping="0.01" friction="0.2"/>
    <limit effort="23.7" lower="-0.686" upper="4.501" velocity="30.1"/>
  </joint>
  <link name="RH_thigh">
    <visual>
      <origin rpy="0 0 0" xyz="0 0 0"/>
      <geometry>
        <mesh filename="package://biqu_go1_description/go1_meshes/thigh_mirror.dae" scale="1 1 1"/>
      </geometry>
      <material name="orange"/>
    </visual>
    <collision>
      <origin rpy="0 1.6707963267948966 0" xyz="-0.015 0 -0.1065"/>
      <geometry>
        <box size="0.213 0.0245 0.034"/>
      </geometry>
    </collision>
    <collision>
      <origin rpy="1.5707963267948966 0 0" xyz="0 0.008 0"/>
      <geometry>
        <cylinder length="0.032" radius="0.041"/>
      </geometry>
    </collision>
    <inertial>
      <origin rpy="0 0 0" xyz="-0.003342 0.018054 -0.033451"/>
      <mass value="0.92"/>
      <inertia ixx="0.004431760472" ixy="-5.7496807e-05" ixz="-0.000218457134" iyy="0.004485671726" iyz="-0.000572001265" izz="0.000740309489"/>
    </inertial>
  </link>
  <joint name="RH_KFE" type="revolute">
    <origin rpy="0 0 0" xyz="0 0 -0.213"/>
    <parent link="RH_thigh"/>
    <child link="RH_calf"/>
    <axis xyz="0 1 0"/>
    <dynamics damping="0.01" friction="0.2"/>
    <limit effort="35.55" lower="-2.818" upper="-0.888" velocity="20.06"/>
  </joint>
  <link name="RH_calf">
    <visual>
      <origin rpy="0 0 0" xyz="0 0 0"/>
      <geometry>
        <mesh filename="package://biqu_go1_description/go1_meshes/calf.dae" scale="1 1 1"/>
      </geometry>
      <material name="orange"/>
    </visual>
    <collision>
      <origin rpy="0 1.5707963267948966 0" xyz="0.0 0 -0.1065"/>
      <geometry>
        <box size="0.213 0.016 0.016"/>
      </geometry>
    </collision>
    <inertial>
      <origin rpy="0 0 0" xyz="0.006197 0.001408 -0.116695"/>
      <mass value="0.135862"/>
      <inertia ixx="0.001088793059" ixy="-2.55679e-07" ixz="7.117814e-06" iyy="0.001100428748" iyz="2.077264e-06" izz="2.4787446e-05"/>
    </inertial>
  </link>
  <joint name="RH_foot_fixed" type="fixed">
    <origin rpy="0 0 0" xyz="0 0 -0.213"/>
    <parent link="RH_calf"/>
    <child link="RH_FOOT"/>
  </joint>
  <link name="RH_FOOT">
    <visual>
      <origin rpy="0 0 0" xyz="0 0 0"/>
      <geometry>
        <sphere radius="0.01"/>
      </geometry>
      <material name="orange"/>
    </visual>
    <collision>
      <origin rpy="0 0 0" xyz="0 0 0"/>
      <geometry>
        <sphere radius="0.02"/>
      </geometry>
    </collision>
    <inertial>
      <mass value="0.06"/>
      <inertia ixx="9.600000000000001e-06" ixy="0.0" ixz="0.0" iyy="9.600000000000001e-06" iyz="0.0" izz="9.600000000000001e-06"/>
    </inertial>
  </link>
  <gazebo reference="RH_foot_fixed">
    <disableFixedJointLumping>true</disableFixedJointLumping>
  </gazebo>
  <gazebo reference="RH_hip">
    <mu1>0.2</mu1>
    <mu2>0.2</mu2>
    <material>Gazebo/DarkGrey</material>
  </gazebo>
  <gazebo reference="RH_thigh">
    <mu1>0.2</mu1>
    <mu2>0.2</mu2>
    <self_collide>0</self_collide>
    <material>Gazebo/DarkGrey</material>
    <kp value="1000000.0"/>
    <kd value="100.0"/>
  </gazebo>
  <gazebo reference="RH_calf">
    <mu1>0.6</mu1>
    <mu2>0.6</mu2>
    <self_collide>1</self_collide>
  </gazebo>
  <gazebo reference="RH_FOOT">
    <mu1>0.6</mu1>
    <mu2>0.6</mu2>
    <self_collide>1</self_collide>
    <material>Gazebo/DarkGrey</material>
    <kp value="1000000.0"/>
    <kd value="100.0"/>
  </gazebo>
  <transmission name="RH_HAA_tran">
    <type>transmission_interface/SimpleTransmission</type>
    <joint name="RH_HAA">
      <hardwareInterface>hardware_interface/EffortJointInterface</hardwareInterface>
    </joint>
    <actuator name="RH_HAA_motor">
      <hardwareInterface>hardware_interface/EffortJointInterface</hardwareInterface>
      <mechanicalReduction>1</mechanicalReduction>
    </actuator>
  </transmission>
  <transmission name="RH_HFE_tran">
    <type>transmission_interface/SimpleTransmission</type>
    <joint name="RH_HFE">
      <hardwareInterface>hardware_interface/EffortJointInterface</hardwareInterface>
    </joint>
    <actuator name="RH_HFE_motor">
      <hardwareInterface>hardware_interface/EffortJointInterface</hardwareInterface>
      <mechanicalReduction>1</mechanicalReduction>
    </actuator>
  </transmission>
  <transmission name="RH_KFE_tran">
    <type>transmission_interface/SimpleTransmission</type>
    <joint name="RH_KFE">
      <hardwareInterface>hardware_interface/EffortJointInterface</hardwareInterface>
    </joint>
    <actuator name="RH_KFE_motor">
      <hardwareInterface>hardware_interface/EffortJointInterface</hardwareInterface>
      <mechanicalReduction>1</mechanicalReduction>
    </actuator>
  </transmission>
  <joint name="LH_HAA" type="revolute">
    <origin rpy="0 0 0" xyz="-0.1881 0.04675 0"/>
    <parent link="base"/>
    <child link="LH_hip"/>
    <axis xyz="1 0 0"/>
    <dynamics damping="0.01" friction="0.2"/>
    <limit effort="23.7" lower="-0.863" upper="0.863" velocity="30.1"/>
  </joint>
  <link name="LH_hip">
    <visual>
      <origin rpy="0 3.141592653589793 0" xyz="0 0 0"/>
      <geometry>
        <mesh filename="package://biqu_go1_description/go1_meshes/hip.dae" scale="1 1 1"/>
      </geometry>
      <material name="orange"/>
    </visual>
    <collision>
      <origin rpy="1.5707963267948966 0 0" xyz="0 0 0"/>
      <geometry>
        <cylinder length="0.04" radius="0.046"/>
      </geometry>
    </collision>
    <inertial>
      <origin rpy="0 0 0" xyz="0.005657 -0.008752 -0.000102"/>
      <mass value="0.591"/>
      <inertia ixx="0.000334008405" ixy="1.0826066e-05" ixz="-1.290732e-06" iyy="0.000619101213" iyz="1.643194e-06" izz="0.00040057614"/>
    </inertial>
  </link>
  <joint name="LH_HFE" type="revolute">
    <origin rpy="0 0 0" xyz="0 0.08 0"/>
    <parent link="LH_hip"/>
    <child link="LH_thigh"/>
    <axis xyz="0 1 0"/>
    <dynamics damping="0.01" friction="0.2"/>
    <limit effort="23.7" lower="-0.686" upper="4.501" velocity="30.1"/>
  </joint>
  <link name="LH_thigh">
    <visual>
      <origin rpy="0 0 0" xyz="0 0 0"/>
      <geometry>
        <mesh filename="package://biqu_go1_description/go1_meshes/thigh.dae" scale="1 1 1"/>
      </geometry>
      <material name="orange"/>
    </visual>
    <collision>
      <origin rpy="0 1.6707963267948966 0" xyz="-0.015 0 -0.1065"/>
      <geometry>
        <box size="0.213 0.0245 0.034"/>
      </geometry>
    </collision>
    <collision>
      <origin rpy="1.5707963267948966 0 0" xyz="0 -0.008 0"/>
      <geometry>
        <cylinder length="0.032" radius="0.041"/>
      </geometry>
    </collision>
    <inertial>
      <origin rpy="0 0 0" xyz="-0.003342 -0.018054 -0.033451"/>
      <mass value="0.92"/>
      <inertia ixx="0.004431760472" ixy="5.7496807e-05" ixz="-0.000218457134" iyy="0.004485671726" iyz="0.000572001265" izz="0.000740309489"/>
    </inertial>
  </link>
  <joint name="LH_KFE" type="revolute">
    <origin rpy="0 0 0" xyz="0 0 -0.213"/>
    <parent link="LH_thigh"/>
    <child link="LH_calf"/>
    <axis xyz="0 1 0"/>
    <dynamics damping="0.01" friction="0.2"/>
    <limit effort="35.55" lower="-2.818" upper="-0.888" velocity="20.06"/>
  </joint>
  <link name="LH_calf">
    <visual>
      <origin rpy="0 0 0" xyz="0 0 0"/>
      <geometry>
        <mesh filename="package://biqu_go1_description/go1_meshes/calf.dae" scale="1 1 1"/>
      </geometry>
      <material name="orange"/>
    </visual>
    <collision>
      <origin rpy="0 1.5707963267948966 0" xyz="0.0 0 -0.1065"/>
      <geometry>
        <box size="0.213 0.016 0.016"/>
      </geometry>
    </collision>
    <inertial>
      <origin rpy="0 0 0" xyz="0.006197 0.001408 -0.116695"/>
      <mass value="0.135862"/>
      <inertia ixx="0.001088793059" ixy="-2.55679e-07" ixz="7.117814e-06" iyy="0.001100428748" iyz="2.077264e-06" izz="2.4787446e-05"/>
    </inertial>
  </link>
  <joint name="LH_foot_fixed" type="fixed">
    <origin rpy="0 0 0" xyz="0 0 -0.213"/>
    <parent link="LH_calf"/>
    <child link="LH_FOOT"/>
  </joint>
  <link name="LH_FOOT">
    <visual>
      <origin rpy="0 0 0" xyz="0 0 0"/>
      <geometry>
        <sphere radius="0.01"/>
      </geometry>
      <material name="orange"/>
    </visual>
    <collision>
      <origin rpy="0 0 0" xyz="0 0 0"/>
      <geometry>
        <sphere radius="0.02"/>
      </geometry>
    </collision>
    <inertial>
      <mass value="0.06"/>
      <inertia ixx="9.600000000000001e-06" ixy="0.0" ixz="0.0" iyy="9.600000000000001e-06" iyz="0.0" izz="9.600000000000001e-06"/>
    </inertial>
  </link>
  <gazebo reference="LH_foot_fixed">
    <disableFixedJointLumping>true</disableFixedJointLumping>
  </gazebo>
  <gazebo reference="LH_hip">
    <mu1>0.2</mu1>
    <mu2>0.2</mu2>
    <material>Gazebo/DarkGrey</material>
  </gazebo>
  <gazebo reference="LH_thigh">
    <mu1>0.2</mu1>
    <mu2>0.2</mu2>
    <self_collide>0</self_collide>
    <material>Gazebo/DarkGrey</material>
    <kp value="1000000.0"/>
    <kd value="100.0"/>
  </gazebo>
  <gazebo reference="LH_calf">
    <mu1>0.6</mu1>
    <mu2>0.6</mu2>
    <self_collide>1</self_collide>
  </gazebo>
  <gazebo reference="LH_FOOT">
    <mu1>0.6</mu1>
    <mu2>0.6</mu2>
    <self_collide>1</self_collide>
    <material>Gazebo/DarkGrey</material>
    <kp value="1000000.0"/>
    <kd value="100.0"/>
  </gazebo>
  <transmission name="LH_HAA_tran">
    <type>transmission_interface/SimpleTransmission</type>
    <joint name="LH_HAA">
      <hardwareInterface>hardware_interface/EffortJointInterface</hardwareInterface>
    </joint>
    <actuator name="LH_HAA_motor">
      <hardwareInterface>hardware_interface/EffortJointInterface</hardwareInterface>
      <mechanicalReduction>1</mechanicalReduction>
    </actuator>
  </transmission>
  <transmission name="LH_HFE_tran">
    <type>transmission_interface/SimpleTransmission</type>
    <joint name="LH_HFE">
      <hardwareInterface>hardware_interface/EffortJointInterface</hardwareInterface>
    </joint>
    <actuator name="LH_HFE_motor">
      <hardwareInterface>hardware_interface/EffortJointInterface</hardwareInterface>
      <mechanicalReduction>1</mechanicalReduction>
    </actuator>
  </transmission>
  <transmission name="LH_KFE_tran">
    <type>transmission_interface/SimpleTransmission</type>
    <joint name="LH_KFE">
      <hardwareInterface>hardware_interface/EffortJointInterface</hardwareInterface>
    </joint>
    <actuator name="LH_KFE_motor">
      <hardwareInterface>hardware_interface/EffortJointInterface</hardwareInterface>
      <mechanicalReduction>1</mechanicalReduction>
    </actuator>
  </transmission>
<link name="arm">
<visual>
<origin xyz="-0.043000000000000093703 -0.056249572745411466346 0.053674572697836049617" rpy="1.570796326794896558 6.9388939039074071039e-18 -2.0296264668928948688e-16" />
<geometry>
<mesh filename="package://biqu_go1_description/arm_meshes/batterycover.stl"/>
</geometry>
<material name="batterycover_material">
<color rgba="0.79607843137254896693 0.82352941176470584317 0.9372549019607843146 1.0"/>
</material>
</visual>
<collision>
<origin xyz="-0.043000000000000093703 -0.056249572745411466346 0.053674572697836049617" rpy="1.570796326794896558 6.9388939039074071039e-18 -2.0296264668928948688e-16" />
<geometry>
<mesh filename="package://biqu_go1_description/arm_meshes/batterycover.stl"/>
</geometry>
</collision>
<visual>
<origin xyz="0.027999999999999969358 0.045620425736449282672 -0.0078254274213730105197" rpy="-1.570796326794896558 -0 -1.570796326794896558" />
<geometry>
<mesh filename="package://biqu_go1_description/arm_meshes/bar.stl"/>
</geometry>
<material name="bar_material">
<color rgba="0.62745098039215685404 0.62745098039215685404 0.62745098039215685404 1.0"/>
</material>
</visual>
<collision>
<origin xyz="0.027999999999999969358 0.045620425736449282672 -0.0078254274213730105197" rpy="-1.570796326794896558 -0 -1.570796326794896558" />
<geometry>
<mesh filename="package://biqu_go1_description/arm_meshes/bar.stl"/>
</geometry>
</collision>
<visual>
<origin xyz="-0.045499999999999984901 0.18587042725458807757 0.00017457269783627965554" rpy="-1.570796326794896558 -0 -1.570796326794896558" />
<geometry>
<mesh filename="package://biqu_go1_description/arm_meshes/nuc_enclosure_right_v8.step.stl"/>
</geometry>
<material name="nuc_enclosure_right_v8.step_material">
<color rgba="0.62745098039215685404 0.62745098039215685404 0.62745098039215685404 1.0"/>
</material>
</visual>
<collision>
<origin xyz="-0.045499999999999984901 0.18587042725458807757 0.00017457269783627965554" rpy="-1.570796326794896558 -0 -1.570796326794896558" />
<geometry>
<mesh filename="package://biqu_go1_description/arm_meshes/nuc_enclosure_right_v8.step.stl"/>
</geometry>
</collision>
<visual>
<origin xyz="-0.029000000000002121303 0.050370427254587735177 0.059174572697836602675" rpy="1.570796326794896558 9.0105057071027178548e-17 1.570796326794896558" />
<geometry>
<mesh filename="package://biqu_go1_description/arm_meshes/cap.stl"/>
</geometry>
<material name="cap_material">
<color rgba="0.62745098039215685404 0.62745098039215685404 0.62745098039215685404 1.0"/>
</material>
</visual>
<collision>
<origin xyz="-0.029000000000002121303 0.050370427254587735177 0.059174572697836602675" rpy="1.570796326794896558 9.0105057071027178548e-17 1.570796326794896558" />
<geometry>
<mesh filename="package://biqu_go1_description/arm_meshes/cap.stl"/>
</geometry>
</collision>
<visual>
<origin xyz="-9.0000000000006741274e-05 -0.001039572745412595256 0.037174572697836277824" rpy="-1.570796326794896558 -0 0" />
<geometry>
<mesh filename="package://biqu_go1_description/arm_meshes/motor.stl"/>
</geometry>
<material name="motor_material">
<color rgba="1 1 1 1.0"/>
</material>
</visual>
<collision>
<origin xyz="-9.0000000000006741274e-05 -0.001039572745412595256 0.037174572697836277824" rpy="-1.570796326794896558 -0 0" />
<geometry>
<mesh filename="package://biqu_go1_description/arm_meshes/motor.stl"/>
</geometry>
</collision>
<visual>
<origin xyz="0.045500000000000005718 0.037870427254587731014 0.00017457269783625623677" rpy="-1.570796326794896558 -2.2204460492410355836e-16 1.57079632679489678" />
<geometry>
<mesh filename="package://biqu_go1_description/arm_meshes/nuc_enclosure_left_v27.step.stl"/>
</geometry>
<material name="nuc_enclosure_left_v27.step_material">
<color rgba="0.62745098039215685404 0.62745098039215685404 0.62745098039215685404 1.0"/>
</material>
</visual>
<collision>
<origin xyz="0.045500000000000005718 0.037870427254587731014 0.00017457269783625623677" rpy="-1.570796326794896558 -2.2204460492410355836e-16 1.57079632679489678" />
<geometry>
<mesh filename="package://biqu_go1_description/arm_meshes/nuc_enclosure_left_v27.step.stl"/>
</geometry>
</collision>
<visual>
<origin xyz="0 -0.001129572745412591589 0.00017457269783627965554" rpy="0 -0 0" />
<geometry>
<mesh filename="package://biqu_go1_description/arm_meshes/base.stl"/>
</geometry>
<material name="base_material">
<color rgba="1 1 1 1.0"/>
</material>
</visual>
<collision>
<origin xyz="0 -0.001129572745412591589 0.00017457269783627965554" rpy="0 -0 0" />
<geometry>
<mesh filename="package://biqu_go1_description/arm_meshes/base.stl"/>
</geometry>
</collision>
<visual>
<origin xyz="-0.0030000000000000581757 0.11587042725458805703 0.0041745726978362797388" rpy="0 -0 -1.2325951644077898923e-32" />
<geometry>
<mesh filename="package://biqu_go1_description/arm_meshes/nuc.stl"/>
</geometry>
<material name="nuc_material">
<color rgba="0.61568627450980395466 0.81176470588235294379 0.92941176470588238168 1.0"/>
</material>
</visual>
<collision>
<origin xyz="-0.0030000000000000581757 0.11587042725458805703 0.0041745726978362797388" rpy="0 -0 -1.2325951644077898923e-32" />
<geometry>
<mesh filename="package://biqu_go1_description/arm_meshes/nuc.stl"/>
</geometry>
</collision>
<visual>
<origin xyz="-0.063000000000000000444 0.045620425736449157772 -0.0078254274213730122545" rpy="-1.570796326794896558 -0 -1.570796326794896558" />
<geometry>
<mesh filename="package://biqu_go1_description/arm_meshes/bar.stl"/>
</geometry>
<material name="bar_material">
<color rgba="0.62745098039215685404 0.62745098039215685404 0.62745098039215685404 1.0"/>
</material>
</visual>
<collision>
<origin xyz="-0.063000000000000000444 0.045620425736449157772 -0.0078254274213730122545" rpy="-1.570796326794896558 -0 -1.570796326794896558" />
<geometry>
<mesh filename="package://biqu_go1_description/arm_meshes/bar.stl"/>
</geometry>
</collision>
<visual>
<origin xyz="-0.040500000000000015155 -0.056249572745412590447 0.053674572697836375745" rpy="1.570796326794896558 1.5919291637703030189e-31 1.3010426069826006369e-16" />
<geometry>
<mesh filename="package://biqu_go1_description/arm_meshes/batterybox.stl"/>
</geometry>
<material name="batterybox_material">
<color rgba="0.79607843137254896693 0.82352941176470584317 0.9372549019607843146 1.0"/>
</material>
</visual>
<collision>
<origin xyz="-0.040500000000000015155 -0.056249572745412590447 0.053674572697836375745" rpy="1.570796326794896558 1.5919291637703030189e-31 1.3010426069826006369e-16" />
<geometry>
<mesh filename="package://biqu_go1_description/arm_meshes/batterybox.stl"/>
</geometry>
</collision>
<visual>
<origin xyz="0 -0.001129572745412591589 0.078174572697836286483" rpy="0 -0 0" />
<geometry>
<mesh filename="package://biqu_go1_description/arm_meshes/base2.stl"/>
</geometry>
<material name="base2_material">
<color rgba="1 1 1 1.0"/>
</material>
</visual>
<collision>
<origin xyz="0 -0.001129572745412591589 0.078174572697836286483" rpy="0 -0 0" />
<geometry>
<mesh filename="package://biqu_go1_description/arm_meshes/base2.stl"/>
</geometry>
</collision>
<inertial>
<origin xyz="-0.00094862752882530869403 0.042039439754247905079 0.02874026670072112391" rpy="0 0 0"/>
<mass value="2.9819518087274810014" />
<inertia ixx="0.028563426842572840758" ixy="0.00053767167140223142818"  ixz="3.2108459365490719234e-05" iyy="0.0044211640677897286883" iyz="0.0005040806111046927402" izz="0.030089818410769811341" />
</inertial>
</link>

<link name="link1">
<visual>
<origin xyz="-0.0054332708436385518391 -1.7564075194265171831e-17 -0.033000000000000001554" rpy="3.141592653589793116 -0 -1.5265782411869662363e-17" />
<geometry>
<mesh filename="package://biqu_go1_description/arm_meshes/link1.stl"/>
</geometry>
<material name="link1_material">
<color rgba="1 1 1 1.0"/>
</material>
</visual>
<collision>
<origin xyz="-0.0054332708436385518391 -1.7564075194265171831e-17 -0.033000000000000001554" rpy="3.141592653589793116 -0 -1.5265782411869662363e-17" />
<geometry>
<mesh filename="package://biqu_go1_description/arm_meshes/link1.stl"/>
</geometry>
</collision>
<visual>
<origin xyz="-0.0054332708436385518391 -1.7564075194265171831e-17 -0.033000000000000001554" rpy="3.141592653589793116 -1.570796326794896558 0" />
<geometry>
<mesh filename="package://biqu_go1_description/arm_meshes/base2.stl"/>
</geometry>
<material name="base2_material">
<color rgba="1 1 1 1.0"/>
</material>
</visual>
<collision>
<origin xyz="-0.0054332708436385518391 -1.7564075194265171831e-17 -0.033000000000000001554" rpy="3.141592653589793116 -1.570796326794896558 0" />
<geometry>
<mesh filename="package://biqu_go1_description/arm_meshes/base2.stl"/>
</geometry>
</collision>
<visual>
<origin xyz="-0.046433270843638380088 9.0000000000024088509e-05 -0.033089999999999925029" rpy="1.570796326794896558 -1.5707963267948961139 0" />
<geometry>
<mesh filename="package://biqu_go1_description/arm_meshes/motor.stl"/>
</geometry>
<material name="motor_material">
<color rgba="1 1 1 1.0"/>
</material>
</visual>
<collision>
<origin xyz="-0.046433270843638380088 9.0000000000024088509e-05 -0.033089999999999925029" rpy="1.570796326794896558 -1.5707963267948961139 0" />
<geometry>
<mesh filename="package://biqu_go1_description/arm_meshes/motor.stl"/>
</geometry>
</collision>
<inertial>
<origin xyz="-0.040852211317392729539 8.6609206749093103081e-05 -0.029620937758826369757" rpy="0 0 0"/>
<mass value="0.64328124355788018907" />
<inertia ixx="0.0002449200641864007484" ixy="2.3827050373876424334e-07"  ixz="-2.102663081365386058e-05" iyy="0.00050526449070353190475" iyz="1.93588620686335655e-07" izz="0.00044515132695697242227" />
</inertial>
</link>

<link name="link2">
<visual>
<origin xyz="-0.20499999999999801714 -4.8572257327350598644e-16 0.05999999999999967859" rpy="-1.2137888792318470409e-15 -1.570796326794896558 0" />
<geometry>
<mesh filename="package://biqu_go1_description/arm_meshes/link2.2.stl"/>
</geometry>
<material name="link2.2_material">
<color rgba="1 1 1 1.0"/>
</material>
</visual>
<collision>
<origin xyz="-0.20499999999999801714 -4.8572257327350598644e-16 0.05999999999999967859" rpy="-1.2137888792318470409e-15 -1.570796326794896558 0" />
<geometry>
<mesh filename="package://biqu_go1_description/arm_meshes/link2.2.stl"/>
</geometry>
</collision>
<visual>
<origin xyz="-0.20499999999999812816 -4.2327252813834093104e-16 0.059999999999999685529" rpy="2.4893298511732086215e-16 6.0581801939752800655e-16 3.1415926535897926719" />
<geometry>
<mesh filename="package://biqu_go1_description/arm_meshes/base2.stl"/>
</geometry>
<material name="base2_material">
<color rgba="1 1 1 1.0"/>
</material>
</visual>
<collision>
<origin xyz="-0.20499999999999812816 -4.2327252813834093104e-16 0.059999999999999685529" rpy="2.4893298511732086215e-16 6.0581801939752800655e-16 3.1415926535897926719" />
<geometry>
<mesh filename="package://biqu_go1_description/arm_meshes/base2.stl"/>
</geometry>
</collision>
<visual>
<origin xyz="2.7755575615628913511e-17 6.9388939039072283776e-18 0.020000000000000003886" rpy="1.570796326794896558 1.570796326794896558 0" />
<geometry>
<mesh filename="package://biqu_go1_description/arm_meshes/link2.stl"/>
</geometry>
<material name="link2_material">
<color rgba="1 1 1 1.0"/>
</material>
</visual>
<collision>
<origin xyz="2.7755575615628913511e-17 6.9388939039072283776e-18 0.020000000000000003886" rpy="1.570796326794896558 1.570796326794896558 0" />
<geometry>
<mesh filename="package://biqu_go1_description/arm_meshes/link2.stl"/>
</geometry>
</collision>
<visual>
<origin xyz="-0.20508999999999993902 8.9999999999472446444e-05 0.019000000000000374228" rpy="-1.570796326794896558 1.0122583203283967912e-15 -1.1794672002304914752e-15" />
<geometry>
<mesh filename="package://biqu_go1_description/arm_meshes/motor.stl"/>
</geometry>
<material name="motor_material">
<color rgba="1 1 1 1.0"/>
</material>
</visual>
<collision>
<origin xyz="-0.20508999999999993902 8.9999999999472446444e-05 0.019000000000000374228" rpy="-1.570796326794896558 1.0122583203283967912e-15 -1.1794672002304914752e-15" />
<geometry>
<mesh filename="package://biqu_go1_description/arm_meshes/motor.stl"/>
</geometry>
</collision>
<inertial>
<origin xyz="-0.17328672464564939815 4.183619830649827452e-05 0.010341353672720928619" rpy="0 0 0"/>
<mass value="0.84537208634905847138" />
<inertia ixx="0.00076159907830105830207" ixy="1.2481861267342365719e-06"  ixz="0.00070910741547682248735" iyy="0.0037852674027457878202" iyz="-6.6015902025999712907e-07" izz="0.0032510342013547530518" />
</inertial>
</link>

<link name="link3">
<visual>
<origin xyz="-0.092500000000000845435 1.5543122344752191566e-15 0.014999999999999534539" rpy="1.5707963267948958919 -1.5553548128009674369e-15 -1.5707963267948972241" />
<geometry>
<mesh filename="package://biqu_go1_description/arm_meshes/servo.stl"/>
</geometry>
<material name="servo_material">
<color rgba="0.61568627450980395466 0.81176470588235294379 0.92941176470588238168 1.0"/>
</material>
</visual>
<collision>
<origin xyz="-0.092500000000000845435 1.5543122344752191566e-15 0.014999999999999534539" rpy="1.5707963267948958919 -1.5553548128009674369e-15 -1.5707963267948972241" />
<geometry>
<mesh filename="package://biqu_go1_description/arm_meshes/servo.stl"/>
</geometry>
</collision>
<visual>
<origin xyz="2.7755575615628913511e-17 0 0.020000000000000010825" rpy="1.57079632679489678 1.570796326794896558 0" />
<geometry>
<mesh filename="package://biqu_go1_description/arm_meshes/link3.stl"/>
</geometry>
<material name="link3_material">
<color rgba="1 1 1 1.0"/>
</material>
</visual>
<collision>
<origin xyz="2.7755575615628913511e-17 0 0.020000000000000010825" rpy="1.57079632679489678 1.570796326794896558 0" />
<geometry>
<mesh filename="package://biqu_go1_description/arm_meshes/link3.stl"/>
</geometry>
</collision>
<visual>
<origin xyz="-0.10180032389301382767 0.015480877538495141366 -9.4974788687557376576e-05" rpy="4.3016806582246644288e-14 -1.5707963267948166219 0" />
<geometry>
<mesh filename="package://biqu_go1_description/arm_meshes/gripperlink2.stl"/>
</geometry>
<material name="gripperlink2_material">
<color rgba="0.79607843137254896693 0.82352941176470584317 0.9372549019607843146 1.0"/>
</material>
</visual>
<collision>
<origin xyz="-0.10180032389301382767 0.015480877538495141366 -9.4974788687557376576e-05" rpy="4.3016806582246644288e-14 -1.5707963267948166219 0" />
<geometry>
<mesh filename="package://biqu_go1_description/arm_meshes/gripperlink2.stl"/>
</geometry>
</collision>
<visual>
<origin xyz="-0.10180032389301330031 0.015480877538495224632 -9.4974788687640643303e-05" rpy="4.7133166719546065429e-14 -1.5707963267948155117 0" />
<geometry>
<mesh filename="package://biqu_go1_description/arm_meshes/gripperlink1.stl"/>
</geometry>
<material name="gripperlink1_material">
<color rgba="0.79607843137254896693 0.82352941176470584317 0.9372549019607843146 1.0"/>
</material>
</visual>
<collision>
<origin xyz="-0.10180032389301330031 0.015480877538495224632 -9.4974788687640643303e-05" rpy="4.7133166719546065429e-14 -1.5707963267948155117 0" />
<geometry>
<mesh filename="package://biqu_go1_description/arm_meshes/gripperlink1.stl"/>
</geometry>
</collision>
<inertial>
<origin xyz="-0.059154639552925582235 -4.1652120917699786521e-06 -0.013202620155315092365" rpy="0 0 0"/>
<mass value="0.16572118754875830859" />
<inertia ixx="5.6397743731799028998e-05" ixy="2.2988205287659273953e-08"  ixz="9.0423920884201157601e-06" iyy="0.00029479933518177962393" iyz="1.60670726097580851e-08" izz="0.00027850551732600084846" />
</inertial>
</link>

<link name="gripper">
<visual>
<origin xyz="0.00067499999999989790389 -0.0040000000000002811085 -0.016499999999999848121" rpy="3.141592653589793116 -2.6886223288726292837e-15 3.1415926535897691352" />
<geometry>
<mesh filename="package://biqu_go1_description/arm_meshes/gripper_4.stl"/>
</geometry>
<material name="gripper_4_material">
<color rgba="0.89411764705882357251 0.91372549019607840481 0.92941176470588238168 1.0"/>
</material>
</visual>
<collision>
<origin xyz="0.00067499999999989790389 -0.0040000000000002811085 -0.016499999999999848121" rpy="3.141592653589793116 -2.6886223288726292837e-15 3.1415926535897691352" />
<geometry>
<mesh filename="package://biqu_go1_description/arm_meshes/gripper_4.stl"/>
</geometry>
</collision>
<visual>
<origin xyz="-0.0078250000000000818901 -0.0040000000000001423306 -0.032499999999999779066" rpy="0.094984357307938374615 -2.818051666908969439e-16 1.5707963267948961139" />
<geometry>
<mesh filename="package://biqu_go1_description/arm_meshes/gripper_2.stl"/>
</geometry>
<material name="gripper_2_material">
<color rgba="0.89411764705882357251 0.91372549019607840481 0.92941176470588238168 1.0"/>
</material>
</visual>
<collision>
<origin xyz="-0.0078250000000000818901 -0.0040000000000001423306 -0.032499999999999779066" rpy="0.094984357307938374615 -2.818051666908969439e-16 1.5707963267948961139" />
<geometry>
<mesh filename="package://biqu_go1_description/arm_meshes/gripper_2.stl"/>
</geometry>
</collision>
<visual>
<origin xyz="-0.00076017147315771138594 -0.0015000000000007507328 -0.047649123529255869858" rpy="3.1415926535897922278 0.094984357307933767189 -2.6979513969416627637e-14" />
<geometry>
<mesh filename="package://biqu_go1_description/arm_meshes/gripper_3.stl"/>
</geometry>
<material name="gripper_3_material">
<color rgba="0 0.50196078431372548323 1 1.0"/>
</material>
</visual>
<collision>
<origin xyz="-0.00076017147315771138594 -0.0015000000000007507328 -0.047649123529255869858" rpy="3.1415926535897922278 0.094984357307933767189 -2.6979513969416627637e-14" />
<geometry>
<mesh filename="package://biqu_go1_description/arm_meshes/gripper_3.stl"/>
</geometry>
</collision>
<visual>
<origin xyz="9.0971822251845191332e-05 -0.0015000000000004731771 -0.046531684784240717745" rpy="-3.1415926535897926719 -0.043187700240528231754 3.1415926535897664706" />
<geometry>
<mesh filename="package://biqu_go1_description/arm_meshes/gripper_3.stl"/>
</geometry>
<material name="gripper_3_material">
<color rgba="0 0.50196078431372548323 1 1.0"/>
</material>
</visual>
<collision>
<origin xyz="9.0971822251845191332e-05 -0.0015000000000004731771 -0.046531684784240717745" rpy="-3.1415926535897926719 -0.043187700240528231754 3.1415926535897664706" />
<geometry>
<mesh filename="package://biqu_go1_description/arm_meshes/gripper_3.stl"/>
</geometry>
</collision>
<visual>
<origin xyz="0.00067499999999995341504 0.0089999999999998969713 -0.016499999999999848121" rpy="-3.141592653589793116 -3.1341729464866167256e-15 3.1415926535897691352" />
<geometry>
<mesh filename="package://biqu_go1_description/arm_meshes/gripper_5.stl"/>
</geometry>
<material name="gripper_5_material">
<color rgba="0.89411764705882357251 0.91372549019607840481 0.92941176470588238168 1.0"/>
</material>
</visual>
<collision>
<origin xyz="0.00067499999999995341504 0.0089999999999998969713 -0.016499999999999848121" rpy="-3.141592653589793116 -3.1341729464866167256e-15 3.1415926535897691352" />
<geometry>
<mesh filename="package://biqu_go1_description/arm_meshes/gripper_5.stl"/>
</geometry>
</collision>
<visual>
<origin xyz="-5.5511151231257827021e-17 0 -0.0011238668575307142472" rpy="-1.570796326794896558 -1.537093985394676151e-17 6.1870996271311447769e-17" />
<geometry>
<mesh filename="package://biqu_go1_description/arm_meshes/gripper_8.stl"/>
</geometry>
<material name="gripper_8_material">
<color rgba="0.90196078431372550543 0.92156862745098033773 0.92941176470588238168 1.0"/>
</material>
</visual>
<collision>
<origin xyz="-5.5511151231257827021e-17 0 -0.0011238668575307142472" rpy="-1.570796326794896558 -1.537093985394676151e-17 6.1870996271311447769e-17" />
<geometry>
<mesh filename="package://biqu_go1_description/arm_meshes/gripper_8.stl"/>
</geometry>
</collision>
<visual>
<origin xyz="0.0091750000000002940315 -0.0040000000000006141754 -0.032499999999999910905" rpy="0.043187700240529459939 -3.5932039344207654432e-16 1.57079632679489678" />
<geometry>
<mesh filename="package://biqu_go1_description/arm_meshes/gripper_1.stl"/>
</geometry>
<material name="gripper_1_material">
<color rgba="0.89411764705882357251 0.91372549019607840481 0.92941176470588238168 1.0"/>
</material>
</visual>
<collision>
<origin xyz="0.0091750000000002940315 -0.0040000000000006141754 -0.032499999999999910905" rpy="0.043187700240529459939 -3.5932039344207654432e-16 1.57079632679489678" />
<geometry>
<mesh filename="package://biqu_go1_description/arm_meshes/gripper_1.stl"/>
</geometry>
</collision>
<visual>
<origin xyz="-0.00024968640208264392122 0.013499999999999054423 -0.016499999999999848121" rpy="1.570796326794871689 -1.5707963267948907848 0" />
<geometry>
<mesh filename="package://biqu_go1_description/arm_meshes/servo.stl"/>
</geometry>
<material name="servo_material">
<color rgba="0.61568627450980395466 0.81176470588235294379 0.92941176470588238168 1.0"/>
</material>
</visual>
<collision>
<origin xyz="-0.00024968640208264392122 0.013499999999999054423 -0.016499999999999848121" rpy="1.570796326794871689 -1.5707963267948907848 0" />
<geometry>
<mesh filename="package://biqu_go1_description/arm_meshes/servo.stl"/>
</geometry>
</collision>
<inertial>
<origin xyz="-0.0019691691678374255957 -0.0012056515638583780326 -0.05307171625105627788" rpy="0 0 0"/>
<mass value="0.045574572086383866032" />
<inertia ixx="7.0377054952081060236e-05" ixy="-6.2977673367866556081e-09"  ixz="-2.8157827238827543481e-06" iyy="7.5407102856481989981e-05" iyz="-8.4256578519192926494e-07" izz="6.9482496526636273771e-06" />
</inertial>
</link>

<joint name="j4" type="revolute">
<origin xyz="-0.11954000000000081227 1.3322676295501878485e-15 0.0089999999999997928879" rpy="1.5707963267948974462 0.28661171544860569727 1.5707963267948994446" />
<parent link="link3" />
<child link="gripper" />
<axis xyz="0 0 1"/>
<limit effort="1" velocity="20" />
<joint_properties friction="0.0"/>
</joint>

<joint name="j3" type="revolute">
<origin xyz="-0.20509002189797093108 -1.4672502470544634967e-05 0.090080000000000437499" rpy="3.141592653589788231 -1.9419648726808066193e-14 2.1321987590919362354" />
<parent link="link2" />
<child link="link3" />
<axis xyz="0 0 1"/>
<limit effort="1" velocity="20" />
<joint_properties friction="0.0"/>
</joint>

<joint name="j2" type="revolute">
<origin xyz="0.02464672915636164155 0.00019467250247003336366 -0.03309002189797083382" rpy="-1.570796326794896558 -1.2791473275524971598 1.5707963267950091346" />
<parent link="link1" />
<child link="link2" />
<axis xyz="0 0 1"/>
<limit effort="1" velocity="20" />
<joint_properties friction="0.0"/>
</joint>

<joint name="base_to_link1" type="revolute">
<origin xyz="-9.0021897970907725772e-05 -0.0011442452478826114701 0.10063457269783626646" rpy="3.141592653589793116 4.758088539404329584e-24 -0.21065212834965882371" />
<parent link="arm" />
<child link="link1" />
<axis xyz="0 0 1"/>
<limit effort="1" velocity="20" />
<joint_properties friction="0.0"/>
</joint>

<joint name="base_to_arm" type="fixed">
<origin xyz="-0.04 0 0.065" rpy="0 0 -1.5708" />
<parent link="base" />
<child link="arm" />
</joint>
</robot>

