<?xml version="1.0" ?>
<!-- =================================================================================== -->
<!-- |    This document was autogenerated by xacro from urdf/huron.xacro               | -->
<!-- |    EDITING THIS FILE BY HAND IS NOT RECOMMENDED                                 | -->
<!-- =================================================================================== -->
<robot name="huron">
  <material name="black">
    <color rgba="0.0 0.0 0.0 1.0"/>
  </material>
  <material name="blue">
    <color rgba="0.0 0.0 0.8 1.0"/>
  </material>
  <material name="green">
    <color rgba="0.0 0.8 0.0 1.0"/>
  </material>
  <material name="grey">
    <color rgba="0.75294 0.75294 0.75294 1"/>
  </material>
  <material name="orange">
    <color rgba="1.0 0.4235294117647059 0.0392156862745098 1.0"/>
  </material>
  <material name="brown">
    <color rgba="0.8705882352941177 0.8117647058823529 0.7647058823529411 1.0"/>
  </material>
  <material name="red">
    <color rgba="0.8 0.0 0.0 1.0"/>
  </material>
  <material name="white">
    <color rgba="1.0 1.0 1.0 1.0"/>
  </material>
  <!-- Right leg -->
  <!-- Right foot sensors -->
  <!-- ros_control plugin -->
  <gazebo>
    <plugin filename="libgazebo_ros_control.so" name="gazebo_ros_control">
      <robotNamespace>/huron</robotNamespace>
    </plugin>
  </gazebo>
  <gazebo>
    <plugin filename="libgazebo_ros_p3d.so" name="ground_truth">
      <frameName>map</frameName>
      <bodyName>base_link</bodyName>
      <topicName>/huron/odom</topicName>
      <updateRate>100.0</updateRate>
    </plugin>
  </gazebo>
  <!-- imu sensor -->
  <gazebo reference="imu_link">
    <gravity>true</gravity>
    <sensor name="imu_sensor" type="imu">
      <always_on>true</always_on>
      <update_rate>100</update_rate>
      <visualize>true</visualize>
      <topic>/huron/sensor/imu</topic>
      <plugin filename="libgazebo_ros_imu_sensor.so" name="imu_plugin">
        <topicName>huron/sensor/imu</topicName>
        <bodyName>imu_link</bodyName>
        <updateRateHZ>10.0</updateRateHZ>
        <gaussianNoise>0.0</gaussianNoise>
        <xyzOffset>0 0 0</xyzOffset>
        <rpyOffset>0 0 0</rpyOffset>
        <frameName>imu_link</frameName>
      </plugin>
      <pose>0 0 0 0 0 0</pose>
    </sensor>
  </gazebo>
  <gazebo reference="r_ankle_roll_joint">
    <provideFeedback>true</provideFeedback>
  </gazebo>
  <gazebo>
    <plugin filename="libgazebo_ros_ft_sensor.so" name="r1_ft_sensor">
      <updateRate>100.0</updateRate>
      <topicName>/huron/sensor/r1_ft_sensor</topicName>
      <jointName>r_ankle_roll_joint</jointName>
      <gaussianNoise>0.0</gaussianNoise>
    </plugin>
  </gazebo>
  <gazebo reference="l_ankle_roll_joint">
    <provideFeedback>true</provideFeedback>
  </gazebo>
  <gazebo>
    <plugin filename="libgazebo_ros_ft_sensor.so" name="l1_ft_sensor">
      <updateRate>100.0</updateRate>
      <topicName>/huron/sensor/l1_ft_sensor</topicName>
      <jointName>l_ankle_roll_joint</jointName>
      <gaussianNoise>0.0</gaussianNoise>
    </plugin>
  </gazebo>
  <gazebo reference="l_hip_yaw_joint">
    <preserveFixedJoint>true</preserveFixedJoint>
  </gazebo>
  <gazebo reference="l_hip_roll_joint">
    <preserveFixedJoint>true</preserveFixedJoint>
  </gazebo>
  <gazebo reference="r_hip_yaw_joint">
    <preserveFixedJoint>true</preserveFixedJoint>
  </gazebo>
  <gazebo reference="r_hip_roll_joint">
    <preserveFixedJoint>true</preserveFixedJoint>
  </gazebo>
  <!-- World -->
  <gazebo reference="world"/>
  <!-- Map -->
  <gazebo reference="map"/>
  <!-- Base -->
  <gazebo reference="base_link"/>
  <!-- IMU -->
  <gazebo reference="imu_link"/>
  <!-- Body-->
  <gazebo reference="base_footprint">
    <mu1>0.2</mu1>
    <mu2>0.2</mu2>
    <material>Gazebo/Grey</material>
    <selfCollide>false</selfCollide>
  </gazebo>
  <!-- Battery -->
  <gazebo reference="battery_link">
    <material>Gazebo/SkyBlue</material>
    <selfCollide>false</selfCollide>
  </gazebo>
  <!-- Upper body visualization -->
  <gazebo reference="upper_body_link">
    <material>Gazebo/SkyBlue</material>
    <selfCollide>false</selfCollide>
  </gazebo>
  <!-- Left Leg -->
  <gazebo reference="l_hip_yaw_link">
    <mu1>0.2</mu1>
    <mu2>0.2</mu2>
    <material>Gazebo/Grey</material>
    <selfCollide>false</selfCollide>
  </gazebo>
  <gazebo reference="l_hip_roll_link">
    <mu1>0.2</mu1>
    <mu2>0.2</mu2>
    <material>Gazebo/Grey</material>
    <selfCollide>false</selfCollide>
  </gazebo>
  <gazebo reference="l_hip_pitch_link">
    <mu1>0.2</mu1>
    <mu2>0.2</mu2>
    <material>Gazebo/Grey</material>
    <selfCollide>false</selfCollide>
  </gazebo>
  <gazebo reference="l_knee_pitch_link">
    <mu1>0.2</mu1>
    <mu2>0.2</mu2>
    <material>Gazebo/Grey</material>
    <selfCollide>false</selfCollide>
  </gazebo>
  <gazebo reference="l_ankle_pitch_link">
    <mu1>0.2</mu1>
    <mu2>0.2</mu2>
    <material>Gazebo/Grey</material>
    <selfCollide>false</selfCollide>
  </gazebo>
  <gazebo reference="l_ankle_roll_link">
    <kp>1e15</kp>
    <kd>1e13</kd>
    <mu1>0.9</mu1>
    <mu2>0.9</mu2>
    <!-- <mu>0.9</mu> -->
    <!--<maxContacts>30</maxContacts>-->
    <fdir1>0 0 1</fdir1>
    <!-- <maxVel>1.0</maxVel> -->
    <!-- <minDepth>0.001</minDepth> -->
    <material>Gazebo/Blue</material>
  </gazebo>
  <!-- Right Leg -->
  <gazebo reference="r_hip_yaw_link">
    <mu1>0.2</mu1>
    <mu2>0.2</mu2>
    <material>Gazebo/Grey</material>
    <selfCollide>false</selfCollide>
  </gazebo>
  <gazebo reference="r_hip_roll_link">
    <mu1>0.2</mu1>
    <mu2>0.2</mu2>
    <material>Gazebo/Grey</material>
    <selfCollide>false</selfCollide>
  </gazebo>
  <gazebo reference="r_hip_pitch_link">
    <mu1>0.2</mu1>
    <mu2>0.2</mu2>
    <material>Gazebo/Grey</material>
    <selfCollide>false</selfCollide>
  </gazebo>
  <gazebo reference="r_knee_pitch_link">
    <mu1>0.2</mu1>
    <mu2>0.2</mu2>
    <material>Gazebo/Grey</material>
    <selfCollide>false</selfCollide>
  </gazebo>
  <gazebo reference="r_ankle_pitch_link">
    <mu1>0.2</mu1>
    <mu2>0.2</mu2>
    <material>Gazebo/Grey</material>
    <selfCollide>false</selfCollide>
  </gazebo>
  <gazebo reference="r_ankle_roll_link">
    <kp>1e15</kp>
    <kd>1e13</kd>
    <mu1>0.9</mu1>
    <mu2>0.9</mu2>
    <!-- <mu>0.9</mu> -->
    <!--<maxContacts>30</maxContacts>-->
    <fdir1>0 0 1</fdir1>
    <!--  <maxVel>1.0</maxVel>  -->
    <!-- <minDepth>0.0001</minDepth> -->
    <material>Gazebo/Blue</material>
  </gazebo>
  <!-- Used for fixing robot -->
  <!--<link name="world"></link> 
    <joint name="world_fixed" type="fixed">
        <origin xyz="0 0 0.764" rpy="0 0 0"/>
        <parent link="world"/>
        <child link="base_link"/>
    </joint> -->
  <link name="base_link"/>
  <joint name="base_fixed" type="fixed">
    <origin rpy="0 0 0" xyz="0 0 0"/>
    <parent link="base_link"/>
    <child link="base_footprint"/>
  </joint>
  <!-- base_link -->
  <link name="base_footprint">
    <visual>
      <origin rpy="0 0 0" xyz="0 0 0"/>
      <geometry>
        <mesh filename="../meshes/base_link.STL" scale="1 1 1"/>
      </geometry>
      <material name="grey"/>
    </visual>
    <collision>
      <origin rpy="0 0 0" xyz="0 0 0"/>
      <geometry>
        <mesh filename="../meshes/base_link.STL" scale="1 1 1"/>
      </geometry>
      <material name="grey"/>
    </collision>
    <inertial>
      <origin rpy="0 0 0" xyz="-1.3585E-07 5.07E-07 0.026975"/>
      <mass value="3.4072"/>
      <inertia ixx="0.00319" ixy="-1.7776E-09" ixz="-1.7316E-09" iyy="0.010531" iyz="6.4623E-09" izz="0.012315"/>
    </inertial>
  </link>
  <!-- Battery -->
  <link name="battery_link">
    <visual>
      <origin rpy="0 0 0" xyz="0 0 0"/>
      <geometry>
        <box size="0.065 0.188 0.151"/>
      </geometry>
      <material name="blue"/>
    </visual>
    <collision>
      <origin rpy="0 0 0" xyz="0 0 0"/>
      <geometry>
        <box size="0.065 0.188 0.151"/>
      </geometry>
      <material name="blue"/>
    </collision>
    <inertial>
      <origin rpy="0 0 0" xyz="0 0 0"/>
      <mass value="3.90089"/>
      <inertia ixx="0.01890143742" ixy="0" ixz="0" iyy="0.0128628597" iyz="0" izz="0.008785454428"/>
    </inertial>
  </link>
  <joint name="battery_fixed" type="fixed">
    <origin rpy="0 0 0" xyz="0 0 0.0895"/>
    <parent link="base_footprint"/>
    <child link="battery_link"/>
  </joint>
  <!-- Upper body visualization -->
  <link name="upper_body_link">
    <visual>
      <origin rpy="0 0 0" xyz="0 0 0"/>
      <geometry>
        <box size="0.065 0.188 0.25"/>
      </geometry>
      <material name="blue"/>
    </visual>
    <collision>
      <origin rpy="0 0 0" xyz="0 0 0"/>
      <geometry>
        <box size="0.065 0.188 0.25"/>
      </geometry>
      <material name="blue"/>
    </collision>
    <inertial>
      <origin rpy="0 0 0" xyz="0 0 0"/>
      <mass value="0.00001"/>
      <inertia ixx="0.000001" ixy="0" ixz="0" iyy="0.000001" iyz="0" izz="0.000001"/>
    </inertial>
  </link>
  <joint name="upper_body_fixed" type="fixed">
    <origin rpy="0 0 0" xyz="0 0 0.1505"/>
    <parent link="battery_link"/>
    <child link="upper_body_link"/>
  </joint>
  <!-- imu joint -->
  <joint name="imu_fixed" type="fixed">
    <origin rpy="0 0 0" xyz="0 0 0"/>
    <parent link="base_footprint"/>
    <child link="imu_link"/>
  </joint>
  <link name="imu_link"/>
  <!-- right hip yaw joint -->
  <joint name="r_hip_yaw_joint" type="revolute">
    <origin rpy="0 0 3.141592654" xyz="0.0775 0 -0.14512"/>
    <parent link="base_footprint"/>
    <child link="r_hip_yaw_link"/>
    <axis xyz="0 0 1"/>
    <limit effort="1000000" lower="-3.1416" upper="3.1416" velocity="3000"/>
    <dynamics damping="0.5" friction="1"/>
  </joint>
  <transmission name="r_hip_yaw_joint_tran">
    <type>transmission_interface/SimpleTransmission</type>
    <joint name="r_hip_yaw_joint">
      <hardwareInterface>hardware_interface/EffortJointInterface</hardwareInterface>
    </joint>
    <actuator name="r_hip_yaw_joint_motor">
      <hardwareInterface>EffortJointInterface</hardwareInterface>
      <mechanicalReduction>1</mechanicalReduction>
    </actuator>
  </transmission>
  <!-- right hip yaw link -->
  <link name="r_hip_yaw_link">
    <visual>
      <origin rpy="0 0 0" xyz="0 0 0"/>
      <geometry>
        <mesh filename="../meshes/r_hip_yaw_link.STL" scale="1 1 1"/>
      </geometry>
      <material name="grey"/>
    </visual>
    <collision>
      <origin rpy="0 0 0" xyz="0 0 0"/>
      <geometry>
        <mesh filename="../meshes/r_hip_yaw_link.STL" scale="1 1 1"/>
      </geometry>
      <material name="grey"/>
    </collision>
    <inertial>
      <origin rpy="0 0 0" xyz="0.00063365 0.00053469 0.063505"/>
      <mass value="1.6968"/>
      <inertia ixx="0.0022702" ixy="-2.4951E-10" ixz="6.6464E-06" iyy="0.0026746" iyz="5.1468E-09" izz="0.001238"/>
    </inertial>
  </link>
  <!-- right hip roll joint-->
  <joint name="r_hip_roll_joint" type="revolute">
    <origin rpy="1.570796327 0 0" xyz="0 0 0"/>
    <parent link="r_hip_yaw_link"/>
    <child link="r_hip_roll_link"/>
    <axis xyz="0 0 1"/>
    <limit effort="1000000" lower="-0.5236" upper="0.01" velocity="3000"/>
    <dynamics damping="0.5" friction="1"/>
  </joint>
  <transmission name="r_hip_roll_joint_tran">
    <type>transmission_interface/SimpleTransmission</type>
    <joint name="r_hip_roll_joint">
      <hardwareInterface>hardware_interface/EffortJointInterface</hardwareInterface>
    </joint>
    <actuator name="r_hip_roll_joint_motor">
      <hardwareInterface>EffortJointInterface</hardwareInterface>
      <mechanicalReduction>1</mechanicalReduction>
    </actuator>
  </transmission>
  <!-- right hip roll link -->
  <link name="r_hip_roll_link">
    <visual>
      <origin rpy="0 0 0" xyz="0 0 0"/>
      <geometry>
        <mesh filename="../meshes/r_hip_roll_link.STL" scale="1 1 1"/>
      </geometry>
      <material name="grey"/>
    </visual>
    <collision>
      <origin rpy="0 0 0" xyz="0 0 0"/>
      <geometry>
        <mesh filename="../meshes/r_hip_roll_link.STL" scale="1 1 1"/>
      </geometry>
      <material name="grey"/>
    </collision>
    <inertial>
      <origin rpy="0 0 0" xyz="-0.07196 0.0061153 -0.0005211"/>
      <mass value="1.1884"/>
      <inertia ixx="0.00098222" ixy="9.9267E-08" ixz="4.9764E-09" iyy="0.00097045" iyz="9.7285E-08" izz="0.00092365"/>
    </inertial>
  </link>
  <!-- right hip pitch joint -->
  <joint name="r_hip_pitch_joint" type="revolute">
    <origin rpy="-1.570796327 0 -1.570796327" xyz="-1.6665E-05 -0.0165 -5E-05"/>
    <parent link="r_hip_roll_link"/>
    <child link="r_hip_pitch_link"/>
    <axis xyz="0 0 1"/>
    <limit effort="1000000" lower="-1.2217" upper="1.2217" velocity="3000"/>
    <dynamics damping="0.5" friction="1"/>
  </joint>
  <transmission name="r_hip_pitch_joint_tran">
    <type>transmission_interface/SimpleTransmission</type>
    <joint name="r_hip_pitch_joint">
      <hardwareInterface>hardware_interface/EffortJointInterface</hardwareInterface>
    </joint>
    <actuator name="r_hip_pitch_joint_motor">
      <hardwareInterface>EffortJointInterface</hardwareInterface>
      <mechanicalReduction>1</mechanicalReduction>
    </actuator>
  </transmission>
  <!-- right hip pitch link -->
  <link name="r_hip_pitch_link">
    <visual>
      <origin rpy="0 0 0" xyz="0 0 0"/>
      <geometry>
        <mesh filename="../meshes/r_hip_pitch_link.STL" scale="1 1 1"/>
      </geometry>
      <material name="grey"/>
    </visual>
    <collision>
      <origin rpy="0 0 0" xyz="0 0 0"/>
      <geometry>
        <mesh filename="../meshes/r_hip_pitch_link.STL" scale="1 1 1"/>
      </geometry>
      <material name="grey"/>
    </collision>
    <inertial>
      <origin rpy="0 0 0" xyz="0.25103 -7.7295E-06 -0.053135"/>
      <mass value="4.2544"/>
      <inertia ixx="0.0034501" ixy="1.1102E-07" ixz="-0.0019797" iyy="0.010035" iyz="-4.8767E-10" izz="0.01009"/>
    </inertial>
  </link>
  <!-- right knee pitch joint -->
  <joint name="r_knee_pitch_joint" type="revolute">
    <origin rpy="0 0 0" xyz="0.49628 0 0"/>
    <parent link="r_hip_pitch_link"/>
    <child link="r_knee_pitch_link"/>
    <axis xyz="0 0 1"/>
    <limit effort="1000000" lower="-1.570796327" upper="1.570796327" velocity="3000"/>
    <dynamics damping="0.5" friction="1"/>
  </joint>
  <transmission name="r_knee_pitch_joint_tran">
    <type>transmission_interface/SimpleTransmission</type>
    <joint name="r_knee_pitch_joint">
      <hardwareInterface>hardware_interface/EffortJointInterface</hardwareInterface>
    </joint>
    <actuator name="r_knee_pitch_joint_motor">
      <hardwareInterface>EffortJointInterface</hardwareInterface>
      <mechanicalReduction>1</mechanicalReduction>
    </actuator>
  </transmission>
  <!-- right knee pitch link -->
  <link name="r_knee_pitch_link">
    <visual>
      <origin rpy="0 0 0" xyz="0 0 0"/>
      <geometry>
        <mesh filename="../meshes/r_knee_pitch_link.STL" scale="1 1 1"/>
      </geometry>
      <material name="grey"/>
    </visual>
    <collision>
      <origin rpy="0 0 0" xyz="0 0 0"/>
      <geometry>
        <mesh filename="../meshes/r_knee_pitch_link.STL" scale="1 1 1"/>
      </geometry>
      <material name="grey"/>
    </collision>
    <inertial>
      <origin rpy="0 0 0" xyz="0.13397 0.00066001 -0.0028723"/>
      <mass value="3.4875"/>
      <inertia ixx="0.0064814" ixy="1.2524E-05" ixz="2.7966E-05" iyy="0.019762" iyz="-1.0417E-05" izz="0.017354"/>
    </inertial>
  </link>
  <!-- right ankle pitch joint -->
  <joint name="r_ankle_pitch_joint" type="revolute">
    <origin rpy="0 0 0.0" xyz="0.37 0 0"/>
    <parent link="r_knee_pitch_link"/>
    <child link="r_ankle_pitch_link"/>
    <axis xyz="0 0 1"/>
    <limit effort="1000000" lower="-0.5236" upper="0.1745" velocity="3000"/>
    <dynamics damping="0.5" friction="1"/>
  </joint>
  <transmission name="r_ankle_pitch_joint_tran">
    <type>transmission_interface/SimpleTransmission</type>
    <joint name="r_ankle_pitch_joint">
      <hardwareInterface>hardware_interface/EffortJointInterface</hardwareInterface>
    </joint>
    <actuator name="r_ankle_pitch_joint_motor">
      <hardwareInterface>EffortJointInterface</hardwareInterface>
      <mechanicalReduction>1</mechanicalReduction>
    </actuator>
  </transmission>
  <!-- right ankle pitch link -->
  <link name="r_ankle_pitch_link">
    <visual>
      <origin rpy="0 0 0" xyz="0 0 0"/>
      <geometry>
        <mesh filename="../meshes/r_ankle_pitch_link.STL" scale="1 1 1"/>
      </geometry>
      <material name="">
        <color rgba="0.77647 0.75686 0.73725 1"/>
      </material>
    </visual>
    <collision>
      <origin rpy="0 0 0" xyz="0 0 0"/>
      <geometry>
        <mesh filename="../meshes/r_ankle_pitch_link.STL" scale="1 1 1"/>
      </geometry>
      <material name="">
        <color rgba="0.77647 0.75686 0.73725 1"/>
      </material>
    </collision>
    <inertial>
      <origin rpy="0 0 0" xyz="-0.029808 0.001045 3.1134E-08"/>
      <mass value="2.4242"/>
      <inertia ixx="0.0025143" ixy="-0.00025651" ixz="1.1633E-12" iyy="0.0045125" iyz="6.7197E-10" izz="0.0049235"/>
    </inertial>
  </link>
  <!-- right ankle roll joint -->
  <joint name="r_ankle_roll_joint" type="revolute">
    <origin rpy="1.570796327 0 0" xyz="0 0 0"/>
    <parent link="r_ankle_pitch_link"/>
    <child link="r_ankle_roll_link"/>
    <axis xyz="0 0 1"/>
    <limit effort="1000000" lower="-0.3491" upper="0.3491" velocity="3000"/>
    <dynamics damping="0.5" friction="10"/>
  </joint>
  <transmission name="r_ankle_roll_joint_tran">
    <type>transmission_interface/SimpleTransmission</type>
    <joint name="r_ankle_roll_joint">
      <hardwareInterface>hardware_interface/EffortJointInterface</hardwareInterface>
    </joint>
    <actuator name="r_ankle_roll_joint_motor">
      <hardwareInterface>EffortJointInterface</hardwareInterface>
      <mechanicalReduction>1</mechanicalReduction>
    </actuator>
  </transmission>
  <!-- right ankle roll link -->
  <link name="r_ankle_roll_link">
    <visual>
      <origin rpy="0 0 0" xyz="0 0 0"/>
      <geometry>
        <mesh filename="../meshes/r_ankle_roll_link.STL" scale="1 1 1"/>
      </geometry>
      <material name="">
        <color rgba="0.77647 0.75686 0.73725 1"/>
      </material>
    </visual>
    <collision>
      <origin rpy="0 0 0" xyz="0 0 0"/>
      <geometry>
        <mesh filename="../meshes/r_ankle_roll_link.STL" scale="1 1 1"/>
      </geometry>
      <material name="">
        <color rgba="0.77647 0.75686 0.73725 1"/>
      </material>
    </collision>
    <inertial>
      <origin rpy="0 0 0" xyz="0.07353 -6.708E-05 0.063947"/>
      <mass value="1.8633"/>
      <inertia ixx="0.0086824" ixy="9.8353E-06" ixz="0.00024334" iyy="0.0084059" iyz="-0.00012379" izz="0.0013021"/>
    </inertial>
  </link>
  <!-- right ft fixed joint 1 -->
  <joint name="r1_ft_fixed" type="fixed">
    <origin rpy="0 0 1.570796327" xyz="0.0982708740959065 0.0143480673989493 0.127875866180863"/>
    <axis xyz="0 0 1"/>
    <parent link="r_ankle_roll_link"/>
    <child link="r1_foot_ft_link"/>
    <limit effort="100" lower="0" upper="0" velocity="100"/>
  </joint>
  <!-- right foot ft link 1 -->
  <link name="r1_foot_ft_link">
    <visual>
      <origin rpy=" 0 0 0" xyz="0 0 0"/>
      <geometry>
        <mesh filename="../meshes/r1_foot_ft_link.STL" scale="1 1 1"/>
      </geometry>
      <material name="green"/>
    </visual>
    <!-- <collision>
                <xacro:insert_mesh_r1_foot_ft_link />
            </collision>	    
	    <inertial>
		<xacro:insert_inertia_r1_foot_ft_link />
	    </inertial> -->
  </link>
  <!-- right ft fixed joint 2 -->
  <joint name="r2_ft_fixed" type="fixed">
    <origin rpy="0 0 1.570796327" xyz="0.0983344633797905 -0.0206518748353312 0.127875866180863"/>
    <axis xyz="0 0 1"/>
    <parent link="r_ankle_roll_link"/>
    <child link="r2_foot_ft_link"/>
    <limit effort="100" lower="0" upper="0" velocity="100"/>
  </joint>
  <!-- right foot ft link 2 -->
  <link name="r2_foot_ft_link">
    <visual>
      <origin rpy=" 0 0 0" xyz="0 0 0"/>
      <geometry>
        <mesh filename="../meshes/r2_foot_ft_link.STL" scale="1 1 1"/>
      </geometry>
      <material name="green"/>
    </visual>
    <!-- <collision>
                <xacro:insert_mesh_r2_foot_ft_link />
            </collision>	    
	    <inertial>
		<xacro:insert_inertia_r2_foot_ft_link />
	    </inertial> -->
  </link>
  <!-- right ft fixed joint 3 -->
  <joint name="r3_ft_fixed" type="fixed">
    <origin rpy="0 0 1.570796327" xyz="0.0983275192522874 -0.0168297833346846 0"/>
    <axis xyz="0 0 1"/>
    <parent link="r_ankle_roll_link"/>
    <child link="r3_foot_ft_link"/>
    <limit effort="100" lower="0" upper="0" velocity="100"/>
  </joint>
  <!-- right foot ft link 3 -->
  <link name="r3_foot_ft_link">
    <visual>
      <origin rpy=" 0 0 0" xyz="0 0 0"/>
      <geometry>
        <mesh filename="../meshes/r3_foot_ft_link.STL" scale="1 1 1"/>
      </geometry>
      <material name="green"/>
    </visual>
    <!-- <collision>
                <xacro:insert_mesh_r3_foot_ft_link />
            </collision>	    
	    <inertial>
		<xacro:insert_inertia_r3_foot_ft_link />
	    </inertial> -->
  </link>
  <!-- right ft fixed joint 4 -->
  <joint name="r4_ft_fixed" type="fixed">
    <origin rpy="0 0 1.570796327" xyz="0.0982666399609057 0.0166785619632585 0"/>
    <axis xyz="0 0 1"/>
    <parent link="r_ankle_roll_link"/>
    <child link="r4_foot_ft_link"/>
    <limit effort="100" lower="0" upper="0" velocity="100"/>
  </joint>
  <!-- right4 foot ft link 4 -->
  <link name="r4_foot_ft_link">
    <visual>
      <origin rpy=" 0 0 0" xyz="0 0 0"/>
      <geometry>
        <mesh filename="../meshes/r4_foot_ft_link.STL" scale="1 1 1"/>
      </geometry>
      <material name="green"/>
    </visual>
    <!-- <collision>
                <xacro:insert_mesh_r4_foot_ft_link />
            </collision>	    
	    <inertial>
		<xacro:insert_inertia_r4_foot_ft_link />
	    </inertial> -->
  </link>
  <!-- right ft fixed joint -->
  <joint name="rv_ft_fixed" type="fixed">
    <origin rpy="0 0 0" xyz="-0.0165 0 0.055"/>
    <axis xyz="0 0 0"/>
    <parent link="r4_foot_ft_link"/>
    <child link="r_foot_v_ft_link"/>
    <limit effort="100" lower="0" upper="0" velocity="100"/>
  </joint>
  <!-- right foot ft link -->
  <link name="r_foot_v_ft_link"/>
  <!-- left hip yaw joint -->
  <joint name="l_hip_yaw_joint" type="revolute">
    <origin rpy="0 0 0" xyz="-0.0775 0 -0.1451242"/>
    <parent link="base_footprint"/>
    <child link="l_hip_yaw_link"/>
    <axis xyz="0 0 1"/>
    <limit effort="1000000" lower="-3.1416" upper="3.1416" velocity="3000"/>
    <dynamics damping="0.5" friction="1"/>
  </joint>
  <transmission name="l_hip_yaw_joint_tran">
    <type>transmission_interface/SimpleTransmission</type>
    <joint name="l_hip_yaw_joint">
      <hardwareInterface>hardware_interface/EffortJointInterface</hardwareInterface>
    </joint>
    <actuator name="l_hip_yaw_joint_motor">
      <hardwareInterface>EffortJointInterface</hardwareInterface>
      <mechanicalReduction>1</mechanicalReduction>
    </actuator>
  </transmission>
  <!-- left hip yaw link -->
  <link name="l_hip_yaw_link">
    <visual>
      <origin rpy="0 0 0" xyz="0 0 0"/>
      <geometry>
        <mesh filename="../meshes/l_hip_yaw_link.STL" scale="1 1 1"/>
      </geometry>
      <material name="grey"/>
    </visual>
    <collision>
      <origin rpy="0 0 0" xyz="0 0 0"/>
      <geometry>
        <mesh filename="../meshes/l_hip_yaw_link.STL" scale="1 1 1"/>
      </geometry>
      <material name="grey"/>
    </collision>
    <inertial>
      <origin rpy="0 0 0" xyz="0.00063365 -0.00053469 0.063496"/>
      <mass value="1.6968"/>
      <inertia ixx="0.0022702" ixy="-2.4951E-10" ixz="6.6464E-06" iyy="0.0026746" iyz="-5.1468E-09" izz="0.001238"/>
    </inertial>
  </link>
  <!-- left hip roll joint-->
  <joint name="l_hip_roll_joint" type="revolute">
    <origin rpy="1.570796327 0 3.141592654" xyz="0 0 0"/>
    <parent link="l_hip_yaw_link"/>
    <child link="l_hip_roll_link"/>
    <axis xyz="0 0 1"/>
    <limit effort="1000000" lower="-0.01" upper="0.5236" velocity="3000"/>
    <dynamics damping="0.5" friction="1"/>
  </joint>
  <transmission name="l_hip_roll_joint_tran">
    <type>transmission_interface/SimpleTransmission</type>
    <joint name="l_hip_roll_joint">
      <hardwareInterface>hardware_interface/EffortJointInterface</hardwareInterface>
    </joint>
    <actuator name="l_hip_roll_joint_motor">
      <hardwareInterface>EffortJointInterface</hardwareInterface>
      <mechanicalReduction>1</mechanicalReduction>
    </actuator>
  </transmission>
  <!-- left hip roll link -->
  <link name="l_hip_roll_link">
    <visual>
      <origin rpy="0 0 0" xyz="0 0 0"/>
      <geometry>
        <mesh filename="../meshes/l_hip_roll_link.STL" scale="1 1 1"/>
      </geometry>
      <material name="grey"/>
    </visual>
    <collision>
      <origin rpy="0 0 0" xyz="0 0 0"/>
      <geometry>
        <mesh filename="../meshes/l_hip_roll_link.STL" scale="1 1 1"/>
      </geometry>
      <material name="grey"/>
    </collision>
    <inertial>
      <origin rpy="0 0 0" xyz="0.07196 0.0061153 -0.0005211"/>
      <mass value="1.1884"/>
      <inertia ixx="0.00098222" ixy="-9.9267E-08" ixz="4.9764E-09" iyy="0.00097045" iyz="-9.7285E-08" izz="0.00092365"/>
    </inertial>
  </link>
  <!-- left hip pitch joint -->
  <joint name="l_hip_pitch_joint" type="revolute">
    <origin rpy="-1.570796327 0 -1.570796327" xyz="1.6665E-05 -0.0165 -5E-05"/>
    <parent link="l_hip_roll_link"/>
    <child link="l_hip_pitch_link"/>
    <axis xyz="0 0 1"/>
    <limit effort="1000000" lower="-1.2217" upper="1.2217" velocity="3000"/>
    <dynamics damping="0.5" friction="1"/>
  </joint>
  <transmission name="l_hip_pitch_joint_tran">
    <type>transmission_interface/SimpleTransmission</type>
    <joint name="l_hip_pitch_joint">
      <hardwareInterface>hardware_interface/EffortJointInterface</hardwareInterface>
    </joint>
    <actuator name="l_hip_pitch_joint_motor">
      <hardwareInterface>EffortJointInterface</hardwareInterface>
      <mechanicalReduction>1</mechanicalReduction>
    </actuator>
  </transmission>
  <!-- left hip pitch link -->
  <link name="l_hip_pitch_link">
    <visual>
      <origin rpy="0 0 0" xyz="0 0 0"/>
      <geometry>
        <mesh filename="../meshes/l_hip_pitch_link.STL" scale="1 1 1"/>
      </geometry>
      <material name="grey"/>
    </visual>
    <collision>
      <origin rpy="0 0 0" xyz="0 0 0"/>
      <geometry>
        <mesh filename="../meshes/l_hip_pitch_link.STL" scale="1 1 1"/>
      </geometry>
      <material name="grey"/>
    </collision>
    <inertial>
      <origin rpy="0 0 0" xyz="0.25103 -7.7295E-06 0.053135"/>
      <mass value="4.2544"/>
      <inertia ixx="0.0034501" ixy="-1.1102E-07" ixz="0.0019797" iyy="0.010035" iyz="-4.8767E-10" izz="0.01009"/>
    </inertial>
  </link>
  <!-- left knee pitch joint -->
  <joint name="l_knee_pitch_joint" type="revolute">
    <origin rpy="0 0 0" xyz="0.49628 0 0"/>
    <parent link="l_hip_pitch_link"/>
    <child link="l_knee_pitch_link"/>
    <axis xyz="0 0 1"/>
    <limit effort="1000000" lower="-1.570796327" upper="1.570796327" velocity="3000"/>
    <dynamics damping="0.5" friction="1"/>
  </joint>
  <transmission name="l_knee_pitch_joint_tran">
    <type>transmission_interface/SimpleTransmission</type>
    <joint name="l_knee_pitch_joint">
      <hardwareInterface>hardware_interface/EffortJointInterface</hardwareInterface>
    </joint>
    <actuator name="l_knee_pitch_joint_motor">
      <hardwareInterface>EffortJointInterface</hardwareInterface>
      <mechanicalReduction>1</mechanicalReduction>
    </actuator>
  </transmission>
  <!-- left knee pitch link -->
  <link name="l_knee_pitch_link">
    <visual>
      <origin rpy="0 0 0" xyz="0 0 0"/>
      <geometry>
        <mesh filename="../meshes/l_knee_pitch_link.STL" scale="1 1 1"/>
      </geometry>
      <material name="grey"/>
    </visual>
    <collision>
      <origin rpy="0 0 0" xyz="0 0 0"/>
      <geometry>
        <mesh filename="../meshes/l_knee_pitch_link.STL" scale="1 1 1"/>
      </geometry>
      <material name="grey"/>
    </collision>
    <inertial>
      <origin rpy="0 0 0" xyz="0.13397 0.00066001 0.0028723"/>
      <mass value="3.4875"/>
      <inertia ixx="0.0064814" ixy="1.2524E-05" ixz="-2.7966E-05" iyy="0.019762" iyz="1.0417E-05" izz="0.017354"/>
    </inertial>
  </link>
  <!-- left ankle pitch joint -->
  <joint name="l_ankle_pitch_joint" type="revolute">
    <origin rpy="0 0 0.0" xyz="0.37 0 0"/>
    <parent link="l_knee_pitch_link"/>
    <child link="l_ankle_pitch_link"/>
    <axis xyz="0 0 1"/>
    <limit effort="1000000" lower="-0.5236" upper="0.1745" velocity="3000"/>
    <dynamics damping="0.5" friction="1"/>
  </joint>
  <transmission name="l_ankle_pitch_joint_tran">
    <type>transmission_interface/SimpleTransmission</type>
    <joint name="l_ankle_pitch_joint">
      <hardwareInterface>hardware_interface/EffortJointInterface</hardwareInterface>
    </joint>
    <actuator name="l_ankle_pitch_joint_motor">
      <hardwareInterface>EffortJointInterface</hardwareInterface>
      <mechanicalReduction>1</mechanicalReduction>
    </actuator>
  </transmission>
  <!-- left ankle pitch link -->
  <link name="l_ankle_pitch_link">
    <visual>
      <origin rpy="0 0 0" xyz="0 0 0"/>
      <geometry>
        <mesh filename="../meshes/l_ankle_pitch_link.STL" scale="1 1 1"/>
      </geometry>
      <material name="">
        <color rgba="0.89804 0.91765 0.92941 1"/>
      </material>
    </visual>
    <collision>
      <origin rpy="0 0 0" xyz="0 0 0"/>
      <geometry>
        <mesh filename="../meshes/l_ankle_pitch_link.STL" scale="1 1 1"/>
      </geometry>
      <material name="">
        <color rgba="0.89804 0.91765 0.92941 1"/>
      </material>
    </collision>
    <inertial>
      <origin rpy="0 0 0" xyz="-0.029808 0.001045 3.1134E-08"/>
      <mass value="2.4242"/>
      <inertia ixx="0.0025143" ixy="-0.00025651" ixz="1.1633E-12" iyy="0.0045125" iyz="6.7197E-10" izz="0.0049235"/>
    </inertial>
  </link>
  <!-- left ankle roll pitch -->
  <joint name="l_ankle_roll_joint" type="revolute">
    <origin rpy="1.570796327 0 0" xyz="0 0 0"/>
    <parent link="l_ankle_pitch_link"/>
    <child link="l_ankle_roll_link"/>
    <axis xyz="0 0 1"/>
    <limit effort="1000000" lower="-0.3491" upper="0.3491" velocity="3000"/>
    <dynamics damping="0.5" friction="10"/>
  </joint>
  <transmission name="l_ankle_roll_joint_tran">
    <type>transmission_interface/SimpleTransmission</type>
    <joint name="l_ankle_roll_joint">
      <hardwareInterface>hardware_interface/EffortJointInterface</hardwareInterface>
    </joint>
    <actuator name="l_ankle_roll_joint_motor">
      <hardwareInterface>EffortJointInterface</hardwareInterface>
      <mechanicalReduction>1</mechanicalReduction>
    </actuator>
  </transmission>
  <!-- left ankle roll link -->
  <link name="l_ankle_roll_link">
    <visual>
      <origin rpy="0 0 0" xyz="0 0 0"/>
      <geometry>
        <mesh filename="../meshes/l_ankle_roll_link.STL" scale="1 1 1"/>
      </geometry>
      <material name="">
        <color rgba="0.77647 0.75686 0.73725 1"/>
      </material>
    </visual>
    <collision>
      <origin rpy="0 0 0" xyz="0 0 0"/>
      <geometry>
        <mesh filename="../meshes/l_ankle_roll_link.STL" scale="1 1 1"/>
      </geometry>
      <material name="">
        <color rgba="0.77647 0.75686 0.73725 1"/>
      </material>
    </collision>
    <inertial>
      <origin rpy="0 0 0" xyz="0.07353 6.708E-05 0.063947"/>
      <mass value="1.8633"/>
      <inertia ixx="0.0086824" ixy="-9.8353E-06" ixz="0.00024334" iyy="0.0084059" iyz="0.00012379" izz="0.0013021"/>
    </inertial>
  </link>
  <!-- left ft fixed joint 1 -->
  <joint name="l1_ft_fixed" type="fixed">
    <origin rpy="0 0 1.570796327" xyz="0.0983282135717449 0.0206816111121677 0.127875866180865"/>
    <axis xyz="0 0 1"/>
    <parent link="l_ankle_roll_link"/>
    <child link="l1_foot_ft_link"/>
    <limit effort="100" lower="0" upper="0" velocity="100"/>
  </joint>
  <!-- left foot ft link 1 -->
  <link name="l1_foot_ft_link">
    <visual>
      <origin rpy=" 0 0 0" xyz="0 0 0"/>
      <geometry>
        <mesh filename="../meshes/l1_foot_ft_link.STL" scale="1 1 1"/>
      </geometry>
      <material name="green"/>
    </visual>
    <!-- <collision>
                <xacro:insert_mesh_l1_foot_ft_link />
            </collision>	    
	    <inertial>
		<xacro:insert_inertia_l1_foot_ft_link />
	    </inertial> -->
  </link>
  <!-- left ft fixed joint 2 -->
  <joint name="l2_ft_fixed" type="fixed">
    <origin rpy="0 0 1.570796327" xyz="0.0982752085863122 -0.0143183487516882 0.127875866180865"/>
    <axis xyz="0 0 1"/>
    <parent link="l_ankle_roll_link"/>
    <child link="l2_foot_ft_link"/>
    <limit effort="100" lower="0" upper="0" velocity="100"/>
  </joint>
  <!-- left foot ft link 2 -->
  <link name="l2_foot_ft_link">
    <visual>
      <origin rpy=" 0 0 0" xyz="0 0 0"/>
      <geometry>
        <mesh filename="../meshes/l2_foot_ft_link.STL" scale="1 1 1"/>
      </geometry>
      <material name="green"/>
    </visual>
    <!-- <collision>
                <xacro:insert_mesh_l2_foot_ft_link />
            </collision>	    
	    <inertial>
		<xacro:insert_inertia_l2_foot_ft_link />
	    </inertial> -->
  </link>
  <!-- left ft fixed joint 3 -->
  <joint name="l3_ft_fixed" type="fixed">
    <origin rpy="0 0 1.570796327" xyz="0.0982716792139032 -0.0166488444898757 0"/>
    <axis xyz="0 0 1"/>
    <parent link="l_ankle_roll_link"/>
    <child link="l3_foot_ft_link"/>
    <limit effort="100" lower="0" upper="0" velocity="100"/>
  </joint>
  <!-- left foot ft link 3 -->
  <link name="l3_foot_ft_link">
    <visual>
      <origin rpy=" 0 0 0" xyz="0 0 0"/>
      <geometry>
        <mesh filename="../meshes/l3_foot_ft_link.STL" scale="1 1 1"/>
      </geometry>
      <material name="green"/>
    </visual>
    <!-- <collision>
                <xacro:insert_mesh_l3_foot_ft_link />
            </collision>	    
	    <inertial>
		<xacro:insert_inertia_l3_foot_ft_link />
	    </inertial> -->
  </link>
  <!-- left ft fixed joint 4 -->
  <joint name="l4_ft_fixed" type="fixed">
    <origin rpy="0 0 1.570796327" xyz="0.0983224252792114 0.0168595176863209 0"/>
    <axis xyz="0 0 1"/>
    <parent link="l_ankle_roll_link"/>
    <child link="l4_foot_ft_link"/>
    <limit effort="100" lower="0" upper="0" velocity="100"/>
  </joint>
  <!-- left foot ft link 4 -->
  <link name="l4_foot_ft_link">
    <visual>
      <origin rpy=" 0 0 0" xyz="0 0 0"/>
      <geometry>
        <mesh filename="../meshes/l4_foot_ft_link.STL" scale="1 1 1"/>
      </geometry>
      <material name="green"/>
    </visual>
    <!-- <collision>
                <xacro:insert_mesh_l4_foot_ft_link />
            </collision>	    
	    <inertial>
		<xacro:insert_inertia_l4_foot_ft_link />
	    </inertial> -->
  </link>
  <!-- left ft fixed joint -->
  <joint name="lv_ft_fixed" type="fixed">
    <origin rpy="0 0 0" xyz="-0.0165 0 0.055"/>
    <parent link="l4_foot_ft_link"/>
    <child link="l_foot_v_ft_link"/>
  </joint>
  <!-- left foot ft link -->
  <link name="l_foot_v_ft_link"/>
</robot>

